Workbook
Name ACTION: #REF!
Name ACTION: #REF!

Sheet Cover
B2: INTEGRATION TEST REPORT DOCUMENT
A4: Project Name | B4: Design and Development of a Warehouse and Sales Management System for Viet Tien Company (DDWSMSVTC) | E4: Creator | F4: KhanhTN
A5: Project Code | B5: SEP490 | E5: Issue Date | F5: 46228
A6: Document Code | B6: =B5&"_"&"Integration Test Report"&"_"&"v"&F6 -> SEP490_Integration Test Report_v1.0 | E6: Version | F6: 1.0
A9: Record of change
A10: Effective Date | B10: Version | C10: Change Item | D10: *A,D,M | E10: Change description | F10: Reference
A11: 46228 | B11: 1.0 | C11: All sheets | D11: A | E11: Initial issue of the Level 2 (Integration Test) report: 77 integration test cases across 11 modules, executed with xUnit + WebApplicationFactory, SQL Server 2022 in Testcontainers, Respawn, WireMock.Net and smtp4dev. | F11: SRS v2 (FT-01..FT-12, BR-001..BR-050, NFR), Test Plan.

Sheet Test Cases
D1: TEST CASE LIST
B3: Project Name | D3: Design and Development of a Warehouse and Sales Management System for Viet Tien Company (DDWSMSVTC)
B4: Project Code | D4: SEP490
B5: Test Environment Setup Description | D5: Staging / test environment for Level 2 integration tests: 1. API: ASP.NET Core 8 monolith run through WebApplicationFactory<Program> 2. Database: SQL Server 2022 in Testcontainers.MsSql, schema built from EF Core migrations, reset by Respawn between tests 3. External systems: WireMock.Net (eSMS, Make.com), smtp4dev mail sink, recording fakes for SMS / AI / Cloudinary 4. Realtime: SignalR test client 5. Runtime: Docker Desktop must be running before dotnet test
B8: No | C8: Function Name | D8: Sheet Name | E8: Description | F8: Pre-Condition
B9: 1 | C9: Infrastructure guardrails | NFR-M02 (maintainability) · deployment operations | D9: L2-Infrastructure
B10: 2 | C10: ProcessSePayWebhook — HTTP end-to-end | BR-06, BV-02, idempotency | D10: L2-OrderPayment
B11: 3 | C11: Payment timeout — 15-min boundary | BV-01, BR-07 (ScheduledJobRunnerBackgroundService: OrderSlaJob) | D11: L2-OrderPayment
B12: 4 | C12: ManualConfirm — fallback | BR-08; 4.4.2 rows 5-6 | D12: L2-OrderPayment
B13: 5 | C13: — Authentication bypass driven by an environment variable | SePayController.cs:53 + OrderService.cs:303 | FT-03 NAC-01; NFR-SEC05 | D13: L2-OrderPayment
B14: 6 | C14: PlaceOrderAsync — checkout with real DB | FT-01 AC-04/05, NAC-03/04; FT-02 NAC-01 | D14: L2-OrderFulfilment
B15: 7 | C15: Confirm -> FIFO queue -> Warehouse accept | FT-04 AC-01; BV-03; 4.4.1 | D15: L2-OrderFulfilment
B16: 8 | C16: Goods issue & walk-in — atomic stock | FT-04 AC-02, NAC-03; FT-08 NAC-03 | D16: L2-OrderFulfilment
B17: 9 | C17: Full approval chain | 4.4.3 rows 1-6 | D17: L2-Quotation
B18: 10 | C18: Negotiation chat | quotation messaging | D18: L2-Quotation
B19: 11 | C19: PO lifecycle + receipt posting | D19: L2-Purchasing
B20: 12 | C20: StockTransfer dispatch/receive | D20: L2-InventoryTransfer
... B36: 28 | C36: ⊕ v2.2 — Jobs still missing in v2.1 | QuotationExpiryJob · UpcomingDeliveryReminderJob | FT-02; FT-07 | D36: L2-ScheduledJobs

Sheet Test Statistics
B1: TEST STATISTICS
B3: Project Name | C3: Design and Development of a Warehouse and Sales Management System for Viet Tien Company (DDWSMSVTC) | E3: Creator | G3: KhanhTN
B4: Project Code | C4: SEP490 | E4: Reviewer/Approver | G4: KhanhTN
B5: Document Code | C5: =Cover!B6 -> SEP490_Integration Test Report_v1.0 | E5: Issue Date | H5: 46238
B6: Notes | C6: Level 2 — Integration Test, version 1.0. Level 2 — Integration Test. Release covers 11 modules: L2-Infrastructure, L2-OrderPayment, L2-OrderFulfilment, L2-Quotation, L2-Purchasing, L2-InventoryTransfer, L2-AuthFlow, L2-Workflows, L2-AfterSalesReturn, L2-AdminConfigAudit, L2-ScheduledJobs
B10: No | C10: Module code | D10: Passed | E10: Failed | F10: Pending | G10: N/A | H10: Number of test cases
B11: 1 | C11: ='L2-Infrastructure'!B2 -> L2-Infrastructure | D11: ='L2-Infrastructure'!B6 -> 3 | E11: ='L2-Infrastructure'!C6 -> 0 | F11: ='L2-Infrastructure'!D6 -> 0 | G11: ='L2-Infrastructure'!E6 -> 0 | H11: ='L2-Infrastructure'!B4 -> 3
B12: 2 | C12: ='L2-OrderPayment'!B2 -> L2-OrderPayment | D12: ='L2-OrderPayment'!B6 -> 11 | E12: ='L2-OrderPayment'!C6 -> 0 | F12: ='L2-OrderPayment'!D6 -> 0 | G12: ='L2-OrderPayment'!E6 -> 0 | H12: ='L2-OrderPayment'!B4 -> 11
B13: 3 | C13: ='L2-OrderFulfilment'!B2 -> L2-OrderFulfilment | D13: ='L2-OrderFulfilment'!B6 -> 8 | E13: ='L2-OrderFulfilment'!C6 -> 0 | F13: ='L2-OrderFulfilment'!D6 -> 0 | G13: ='L2-OrderFulfilment'!E6 -> 0 | H13: ='L2-OrderFulfilment'!B4 -> 8
B14: 4 | C14: ='L2-Quotation'!B2 -> L2-Quotation | D14: ='L2-Quotation'!B6 -> 6 | E14: ='L2-Quotation'!C6 -> 0 | F14: ='L2-Quotation'!D6 -> 0 | G14: ='L2-Quotation'!E6 -> 0 | H14: ='L2-Quotation'!B4 -> 6
B15: 5 | C15: ='L2-Purchasing'!B2 -> L2-Purchasing | D15: ='L2-Purchasing'!B6 -> 5 | E15: ='L2-Purchasing'!C6 -> 0 | F15: ='L2-Purchasing'!D6 -> 0 | G15: ='L2-Purchasing'!E6 -> 0 | H15: ='L2-Purchasing'!B4 -> 5
B16: 6 | C16: ='L2-InventoryTransfer'!B2 -> L2-InventoryTransfer | D16: ='L2-InventoryTransfer'!B6 -> 5 | E16: ='L2-InventoryTransfer'!C6 -> 0 | F16: ='L2-InventoryTransfer'!D6 -> 0 | G16: ='L2-InventoryTransfer'!E6 -> 0 | H16: ='L2-InventoryTransfer'!B4 -> 5
B17: 7 | C17: ='L2-AuthFlow'!B2 -> L2-AuthFlow | D17: ='L2-AuthFlow'!B6 -> 4 | E17: ='L2-AuthFlow'!C6 -> 0 | F17: ='L2-AuthFlow'!D6 -> 0 | G17: ='L2-AuthFlow'!E6 -> 0 | H17: ='L2-AuthFlow'!B4 -> 4
B18: 8 | C18: ='L2-Workflows'!B2 -> L2-Workflows | D18: ='L2-Workflows'!B6 -> 6 | E18: ='L2-Workflows'!C6 -> 0 | F18: ='L2-Workflows'!D6 -> 0 | G18: ='L2-Workflows'!E6 -> 0 | H18: ='L2-Workflows'!B4 -> 6
B19: 9 | C19: ='L2-AfterSalesReturn'!B2 -> L2-AfterSalesReturn | D19: ='L2-AfterSalesReturn'!B6 -> 7 | E19: ='L2-AfterSalesReturn'!C6 -> 0 | F19: ='L2-AfterSalesReturn'!D6 -> 0 | G19: ='L2-AfterSalesReturn'!E6 -> 0 | H19: ='L2-AfterSalesReturn'!B4 -> 7
B20: 10 | C20: ='L2-AdminConfigAudit'!B2 -> L2-AdminConfigAudit | D20: ='L2-AdminConfigAudit'!B6 -> 7 | E20: ='L2-AdminConfigAudit'!C6 -> 0 | F20: ='L2-AdminConfigAudit'!D6 -> 0 | G20: ='L2-AdminConfigAudit'!E6 -> 0 | H20: ='L2-AdminConfigAudit'!B4 -> 7
B21: 11 | C21: ='L2-ScheduledJobs'!B2 -> L2-ScheduledJobs | D21: ='L2-ScheduledJobs'!B6 -> 15 | E21: ='L2-ScheduledJobs'!C6 -> 0 | F21: ='L2-ScheduledJobs'!D6 -> 0 | G21: ='L2-ScheduledJobs'!E6 -> 0 | H21: ='L2-ScheduledJobs'!B4 -> 15
C22: Sub total | D22: =SUM(D11:D21) -> 77 | E22: =SUM(E11:E21) -> 0 | F22: =SUM(F11:F21) -> 0 | G22: =SUM(G11:G21) -> 0 | H22: =SUM(H11:H21) -> 77
C24: Test coverage | E24: =ROUND((D22+E22)*100/(H22-G22),2) -> 100 | F24: %
C25: Test successful coverage | E25: =ROUND(D22*100/(H22-G22),2) -> 100 | F25: %

Sheet L2-Infrastructure
A2: Feature | B2: L2-Infrastructure | R2: Passed
A3: Test requirement | B3: Integration test cases for module L2-Infrastructure — 3 test cases. SRS refs: NFR-M02, NFR-SEC06 | R3: Failed
A4: Number of TCs | B4: =COUNTA(F11:F14) -> 3 | R4: Pending
A5: Testing Round | B5: Passed | C5: Failed | D5: Pending | E5: N/A | R5: N/A
A6: Round 1 | B6: =COUNTIF($F11:$F14,B5) -> 3 | C6: =COUNTIF($F11:$F14,C5) -> 0 | D6: =COUNTIF($F11:$F14,D5) -> 0 | E6: =COUNTIF($F11:$F14,E5) -> 0
A7: Round 2 | B7: =COUNTIF($I11:$I14,B5) -> 3 | C7: =COUNTIF($I11:$I14,C5) -> 0 | D7: =COUNTIF($I11:$I14,D5) -> 0 | E7: =COUNTIF($I11:$I14,E5) -> 0
A8: Round 3 | B8: =COUNTIF($L11:$L14,B5) -> 3 | C8: =COUNTIF($L11:$L14,C5) -> 0 | D8: =COUNTIF($L11:$L14,D5) -> 0 | E8: =COUNTIF($L11:$L14,E5) -> 0
A10: Test Case ID | B10: Test Case Description | C10: Test Case Procedure | D10: Expected Results | E10: Pre-conditions | F10: Round 1 | G10: Test date | H10: Tester | I10: Round 2 | J10: Test date | K10: Tester | L10: Round 3 | M10: Test date | N10: Tester | O10: Note
A11: Infrastructure guardrails | NFR-M02 (maintainability) · deployment operations
A12: L2-INFRA-01 | B12: No pending EF migration drift — schema built from migrations matches the model | C12: (no HTTP) EF migration + schema check Compare the model snapshot with the actual schema: context.Database.GetPendingMigrations() is empty AND `dotnet ef migrations has-pending-model-changes` returns exit code 0 | D12: No pending model change Every DbSet in ApplicationDbContext can be queried (SELECT TOP 1) without an "Invalid column name" error | E12: Database built CLEAN from migrations inside the container (no manual patching) | F12: Passed | G12: 46235 | H12: KhanhTN | I12: Passed | J12: 46236 | K12: KhanhTN | L12: Passed | M12: 46236 | N12: KhanhTN | O12: SRS: NFR-M02; operations | Technique: Schema Drift Guard | Negative: No | Priority: Critical | Defect: GH-03 | Env: VietTien.API (WebApplicationFactory) + SQL Server · SQL Server 2022 (Testcontainers.MsSql) + Respawn reset MIGRATION DRIFT -> fixed
A13: L2-INFRA-02 | B13: No real outbound call escapes the test host (SMS / webhook / AI / Cloudinary) | C13: (no HTTP) SqlServerTestBase teardown assertion After EVERY L2 test: the shared SqlServerTestBase teardown inspects the recording fakes | D13: Sms / MakeWebhook / AiGenerator / Cloudinary are NEVER called (unless a test sets an explicit opt-out flag) Email is NOT asserted empty (several legitimate mail flows exist) — Factory.Email.Sent is exposed so tests can assert the content themselves | E13: Test host runs UseEnvironment("Test") with appsettings.Test.json (all credentials empty/fake) | F13: Passed | G13: 46235 | H13: KhanhTN | I13: Passed | J13: 46236 | K13: KhanhTN | L13: Passed | M13: 46236 | N13: KhanhTN | O13: SRS: NFR-SEC06; NFR-A02 | Technique: Outbound IO Guard | Negative: Yes | Priority: Critical | Env: VietTien.API (WebApplicationFactory) + SQL Server · SQL Server 2022 (Testcontainers.MsSql) + Respawn reset · Recording fake: ISmsService, IEmailService, IMakeWebhookService, IAiGeneratorService, ICloudinaryService
A14: L2-INFRA-03 | B14: Test host loads no real third-party credentials | C14: (no HTTP) test host IConfiguration Read the test host's IConfiguration | D14: No real credential is loaded (eSMS/Gemini/Cloudinary/SMTP/MakeCom are all empty or fake) JwtSettings:SecretKey is a fake value but long enough to sign/verify | E14: Test host starts up | F14: Passed | G14: 46235 | H14: KhanhTN | I14: Passed | J14: 46236 | K14: KhanhTN | L14: Passed | M14: 46236 | N14: KhanhTN | O14: SRS: NFR-SEC06 | Technique: Config Isolation | Negative: Yes | Priority: Critical | Env: VietTien.API (WebApplicationFactory) + SQL Server · SQL Server 2022 (Testcontainers.MsSql) + Respawn reset

Sheet L2-OrderPayment
A2: Feature | B2: L2-OrderPayment | R2: Passed
A3: Test requirement | B3: Integration test cases for module L2-OrderPayment — 11 test cases. SRS refs: FT-03 | R3: Failed
A4: Number of TCs | B4: =COUNTA(F11:F25) -> 11 | R4: Pending
A5: Testing Round | B5: Passed | C5: Failed | D5: Pending | E5: N/A | R5: N/A
A6: Round 1 | B6: =COUNTIF($F11:$F25,B5) -> 11 | C6: =COUNTIF($F11:$F25,C5) -> 0 | D6: =COUNTIF($F11:$F25,D5) -> 0 | E6: =COUNTIF($F11:$F25,E5) -> 0
A7: Round 2 | B7: =COUNTIF($I11:$I25,B5) -> 11 | C7: =COUNTIF($I11:$I25,C5) -> 0 | D7: =COUNTIF($I11:$I25,D5) -> 0 | E7: =COUNTIF($I11:$I25,E5) -> 0
A8: Round 3 | B8: =COUNTIF($L11:$L25,B5) -> 11 | C8: =COUNTIF($L11:$L25,C5) -> 0 | D8: =COUNTIF($L11:$L25,D5) -> 0 | E8: =COUNTIF($L11:$L25,E5) -> 0
A10: Test Case ID | B10: Test Case Description | C10: Test Case Procedure | D10: Expected Results | E10: Pre-conditions | F10: Round 1 | G10: Test date | H10: Tester | I10: Round 2 | J10: Test date | K10: Tester | L10: Round 3 | M10: Test date | N10: Tester | O10: Note
A11: ProcessSePayWebhook — HTTP end-to-end | BR-06, BV-02, idempotency
A12: L2-PAY-01 | B12: Valid SePay webhook -> order Paid + transaction row in one transaction | C12: POST /api/webhooks/sepay-callback POST /api/webhooks/sepay-callback body: {referenceCode:'ORD-001', transferAmount:5000000, id:'txn-001'} header: Authorization = valid configured token | D12: HTTP 200/201 DB: Order.PaymentStatus = Paid (locked); PaymentTransaction row with TransactionId='txn-001' SignalR: SalesHub receives payment notification Order row + transaction row committed in ONE transaction | E12: Order ORD-001: PaymentStatus=Pending Payment, total=5,000,000 PaymentTransactions: empty SePay Api-Key configured in test appsettings | F12: Passed | G12: 46235 | H12: KhanhTN | I12: Passed | J12: 46236 | K12: KhanhTN | L12: Passed | M12: 46236 | N12: KhanhTN | O12: SRS: FT-03 AC-01; AC-02; BR-009; NFR-SEC05 | Technique: Happy Path + Transaction Boundary | Negative: No | Priority: Critical | Env: VietTien.API (WebApplicationFactory) + SQL Server + SignalR test client · SQL Server 2022 (Testcontainers.MsSql) + Respawn reset · None (SePay is inbound)
A13: L2-PAY-02 | B13: Webhook with a wrong token -> 401, nothing written | C13: POST /api/webhooks/sepay-callback POST /api/webhooks/sepay-callback with SAME body but Authorization = 'WRONG-TOKEN' | D13: HTTP 401 DB: Order.PaymentStatus unchanged (still Pending Payment) No PaymentTransaction row created Security alert logged | E13: Order ORD-001: Pending Payment, total=5,000,000 | F13: Passed | G13: 46235 | H13: KhanhTN | I13: Passed | J13: 46236 | K13: KhanhTN | L13: Passed | M13: 46236 | N13: KhanhTN | O13: SRS: FT-03 NAC-01; NFR-SEC05 | Technique: Error Path | Negative: Yes | Priority: Critical | Env: VietTien.API (WebApplicationFactory) + SQL Server · SQL Server 2022 (Testcontainers.MsSql) + Respawn reset
A14: L2-PAY-03 | B14: Transferred amount off by ±1 VND -> rejected, routed to reconciliation | C14: POST /api/webhooks/sepay-callback POST /api/webhooks/sepay-callback with valid token, transferAmount = total ±1 VND | D14: Both cases rejected/flagged (no auto-Paid) DB: status unchanged; mismatch routed to PaymentException list | E14: Order ORD-001: total=5,000,000 ([Theory]: amount 5,000,001 and 4,999,999) | F14: Passed | G14: 46235 | H14: KhanhTN | I14: Passed | J14: 46236 | K14: KhanhTN | L14: Passed | M14: 46236 | N14: KhanhTN | O14: SRS: FT-03 NAC-01; BV-01 | Technique: BVA | Negative: Yes | Priority: Critical | Env: VietTien.API (WebApplicationFactory) + SQL Server · SQL Server 2022 (Testcontainers.MsSql) + Respawn reset
A15: L2-PAY-04 | B15: Same webhook txn id delivered twice -> no duplicate transaction | C15: POST /api/webhooks/sepay-callback POST /api/webhooks/sepay-callback with IDENTICAL payload (txn-001) a SECOND time | D15: HTTP 200 (accepted quietly) — no exception DB: still exactly 1 PaymentTransaction row; status still Paid No second SignalR notification | E15: Webhook txn-001 already processed: Order Paid; 1 PaymentTransaction row | F15: Passed | G15: 46235 | H15: KhanhTN | I15: Passed | J15: 46236 | K15: KhanhTN | L15: Passed | M15: 46236 | N15: KhanhTN | O15: SRS: FT-03 NAC-02; BR-029 | Technique: Idempotency | Negative: No | Priority: Critical | Env: VietTien.API (WebApplicationFactory) + SQL Server · SQL Server 2022 (Testcontainers.MsSql) + Respawn reset
A16: Payment timeout — 15-min boundary | BV-01, BR-07 (ScheduledJobRunnerBackgroundService: OrderSlaJob)
A17: L2-PAY-05 | B17: Expiry job releases the over-15-minute hold and leaves the fresh order alone | C17: (job) Factory.RunJobAsync<SePayReservationExpiryJob>() Factory.RunJobAsync<SePayReservationExpiryJob>() | D17: Order A: the reservation IS released; Reserved returns to 0; OnHandQuantity unchanged; RawAvailable() rises by exactly the released amount Order B: NOT touched No order ends with negative stock | E17: 2 SePay orders awaiting payment with InventoryReservation holding stock: Order A: CreatedAt backdated to NOW - 20 minutes (clearly expired) Order B: CreatedAt = NOW (just created) SystemConfig SEPAY_RESERVATION_MINUTES = 15 | F17: Passed | G17: 46235 | H17: KhanhTN | I17: Passed | J17: 46236 | K17: KhanhTN | L17: Passed | M17: 46236 | N17: KhanhTN | O17: SRS: FT-03 NAC-03; BV-01; BR-008; BR-033 | Technique: Workflow + Job boundary | Negative: No | Priority: Critical | Env: VietTien.API (WebApplicationFactory) + SQL Server · SQL Server 2022 (Testcontainers.MsSql) + Respawn reset
A18: L2-PAY-06 | B18: Hold at 10 minutes -> expiry job leaves it untouched | C18: (job) Factory.RunJobAsync<SePayReservationExpiryJob>() Factory.RunJobAsync<SePayReservationExpiryJob>() | D18: The reservation is STILL held: Reserved P1 = 3, nothing released The order stays in awaiting-payment state | E18: SePay order awaiting payment, CreatedAt backdated to NOW - 10 minutes (still within the window) SystemConfig SEPAY_RESERVATION_MINUTES = 15 Reserved P1 = 3 | F18: Passed | G18: 46235 | H18: KhanhTN | I18: Passed | J18: 46236 | K18: KhanhTN | L18: Passed | M18: 46236 | N18: KhanhTN | O18: SRS: FT-03 BV-01; BR-008 | Technique: Workflow + Job boundary | Negative: No | Priority: Critical | Env: VietTien.API (WebApplicationFactory) + SQL Server · SQL Server 2022 (Testcontainers.MsSql) + Respawn reset
A19: ManualConfirm — fallback | BR-08; 4.4.2 rows 5-6
A20: L2-PAY-07 | B20: Manual confirm with a bank reference -> order Paid and released to fulfilment | C20: POST /api/orders/{orderId POST /api/orders/{orderId}/manual-confirm body: {bankRef:'FT2026...', note} | D20: HTTP 200; DB: PaymentStatus = Paid (locked), ConfirmedBy = admin 'PAID' flag available for delivery invoice Order released to fulfilment | E20: Order ORD-002: Awaiting Manual Verify Admin user seeded with valid JWT | F20: Passed | G20: 46235 | H20: KhanhTN | I20: Passed | J20: 46236 | K20: KhanhTN | L20: Passed | M20: 46236 | N20: KhanhTN | O20: SRS: FT-03 AC-05; NAC-03; BR-016 | Technique: Happy Path | Negative: No | Priority: Critical | Env: VietTien.API (WebApplicationFactory) + SQL Server · SQL Server 2022 (Testcontainers.MsSql) + Respawn reset
A21: L2-PAY-08 | B21: Manual confirm with no bank reference -> 422, order cancelled, stock released | C21: POST /api/orders/{orderId POST /api/orders/{orderId}/manual-confirm with empty/absent bankRef | D21: HTTP 422; DB: order cancelled per NAC-02 Reserved stock released; no Paid state | E21: Order ORD-003: Awaiting Manual Verify; no matching bank record in request | F21: Passed | G21: 46235 | H21: KhanhTN | I21: Passed | J21: 46236 | K21: KhanhTN | L21: Passed | M21: 46236 | N21: KhanhTN | O21: SRS: FT-03 NAC-04 | Technique: Error Path | Negative: Yes | Priority: Critical | Env: VietTien.API (WebApplicationFactory) + SQL Server · SQL Server 2022 (Testcontainers.MsSql) + Respawn reset
A22: L2-PAY-09 | B22: Webhook and manual confirm fired together -> exactly one wins | C22: POST /api/webhooks/sepay-callback + POST /api/orders/{orderId}/manual-confirm (parallel) Fire webhook POST and manual-confirm POST simultaneously (Task.WhenAll + barrier) | D22: Exactly ONE path wins: final state Paid with exactly 1 PaymentTransaction row Loser gets 409/422 — no duplicate ledger entry, no double SignalR notify | E22: Order ORD-004: Pending Payment near expiry Two triggers prepared: valid webhook + manual confirm | F22: Passed | G22: 46235 | H22: KhanhTN | I22: Passed | J22: 46236 | K22: KhanhTN | L22: Passed | M22: 46236 | N22: KhanhTN | O22: SRS: FT-03 NAC-02; BR-029; NFR-A05 | Technique: Concurrency | Negative: No | Priority: Critical | Defect: GH-02 | Env: VietTien.API (WebApplicationFactory) + SQL Server · SQL Server 2022 (Testcontainers.MsSql) + Respawn reset
A23: — Authentication bypass driven by an environment variable | SePayController.cs:53 + OrderService.cs:303 | FT-03 NAC-01; NFR-SEC05
A24: L2-PAY-10 | B24: Missing token accepted when ASPNETCORE_ENVIRONMENT=Development (bypass) | C24: POST /api/webhooks/sepay-callback POST /api/webhooks/sepay-callback with NO token and a valid body | D24: PER SRS: 401; PaymentStatus stays Pending; 0 PaymentTransaction; security alert logged ACTUAL: 200 and the order is fully moved to Paid | E24: Order ORD-001 PaymentStatus = Pending, FinalPayment = 5,000,000 PROCESS environment variable ASPNETCORE_ENVIRONMENT explicitly set to "Development" (the old value must be restored in finally — it is process-wide) | F24: Passed | G24: 46235 | H24: KhanhTN | I24: Passed | J24: 46236 | K24: KhanhTN | L24: Passed | M24: 46236 | N24: KhanhTN | O24: SRS: FT-03 NAC-01; NFR-SEC05; BR-009 | Technique: Guard-FALSE | Negative: Yes | Priority: Critical | Defect: GH-01 | Env: VietTien.API (WebApplicationFactory) + SQL Server · SQL Server 2022 (Testcontainers.MsSql) + Respawn reset
A25: L2-PAY-11 | B25: Missing token outside Development -> 401, nothing written | C25: POST /api/webhooks/sepay-callback POST /api/webhooks/sepay-callback with NO token | D25: 401 "Missing Token"; PaymentStatus stays Pending; 0 PaymentTransaction | E25: Order ORD-001 PaymentStatus = Pending ASPNETCORE_ENVIRONMENT != "Development" (restored in finally) | F25: Passed | G25: 46235 | H25: KhanhTN | I25: Passed | J25: 46236 | K25: KhanhTN | L25: Passed | M25: 46236 | N25: KhanhTN | O25: SRS: FT-03 NAC-01; NFR-SEC05 | Technique: Guard-TRUE | Negative: Yes | Priority: Critical | Env: VietTien.API (WebApplicationFactory) + SQL Server · SQL Server 2022 (Testcontainers.MsSql) + Respawn reset

Sheet L2-OrderFulfilment
A2: Feature | B2: L2-OrderFulfilment | R2: Passed
A3: Test requirement | B3: Integration test cases for module L2-OrderFulfilment — 8 test cases. SRS refs: FT-01, FT-02, FT-05 | R3: Failed
A4: Number of TCs | B4: =COUNTA(F11:F21) -> 8 | R4: Pending
A5: Testing Round | B5: Passed | C5: Failed | D5: Pending | E5: N/A | R5: N/A
A6: Round 1 | B6: =COUNTIF($F11:$F21,B5) -> 8 | C6: =COUNTIF($F11:$F21,C5) -> 0 | D6: =COUNTIF($F11:$F21,D5) -> 0 | E6: =COUNTIF($F11:$F21,E5) -> 0
A7: Round 2 | B7: =COUNTIF($I11:$I21,B5) -> 8 | C7: =COUNTIF($I11:$I21,C5) -> 0 | D7: =COUNTIF($I11:$I21,D5) -> 0 | E7: =COUNTIF($I11:$I21,E5) -> 0
A8: Round 3 | B8: =COUNTIF($L11:$L21,B5) -> 8 | C8: =COUNTIF($L11:$L21,C5) -> 0 | D8: =COUNTIF($L11:$L21,D5) -> 0 | E8: =COUNTIF($L11:$L21,E5) -> 0
A10: Test Case ID | B10: Test Case Description | C10: Test Case Procedure | D10: Expected Results | E10: Pre-conditions | F10: Round 1 | G10: Test date | H10: Tester | I10: Round 2 | J10: Test date | K10: Tester | L10: Round 3 | M10: Test date | N10: Tester | O10: Note
A11: PlaceOrderAsync — checkout with real DB | FT-01 AC-04/05, NAC-03/04; FT-02 NAC-01
A12: L2-FUL-01 | B12: Checkout writes order, items, invoice email and notifications in one transaction | C12: POST /api/orders POST /api/orders (checkout) as U1 | D12: HTTP 200; DB: Order 'Order Received' + OrderItems match cart smtp4dev: 1 invoice email captured with PDF/lines Sales role notifications created; cart cleared All rows in one transaction | E12: Seed: customer U1 with cart (2 items, in stock, prices locked < 24h) | F12: Passed | G12: 46235 | H12: KhanhTN | I12: Passed | J12: 46236 | K12: KhanhTN | L12: Passed | M12: 46236 | N12: KhanhTN | O12: SRS: FT-01 AC-05; FT-03 AC-04; BR-030 | Technique: Happy Path + Transaction Boundary | Negative: No | Priority: Critical | Env: VietTien.API (WebApplicationFactory) + SQL Server + SignalR · SQL Server 2022 (Testcontainers.MsSql) + Respawn reset · SMTP -> smtp4dev container (capture invoice email)
A13: L2-FUL-02 | B13: Checkout with depleted stock -> full rollback, cart intact | C13: POST /api/orders POST /api/orders as U1 | D13: HTTP 4xx naming product DB: NO Order row, NO OrderItems, cart intact, stock untouched — full rollback | E13: Cart: P1 qty=5; Inventory(P1) = 0 (depleted after add-to-cart) | F13: Passed | G13: 46235 | H13: KhanhTN | I13: Passed | J13: 46236 | K13: KhanhTN | L13: Passed | M13: 46236 | N13: KhanhTN | O13: SRS: FT-01 NAC-03; FT-05 NAC-01 | Technique: Error Path + Rollback | Negative: Yes | Priority: Critical | Env: VietTien.API (WebApplicationFactory) + SQL Server · SQL Server 2022 (Testcontainers.MsSql) + Respawn reset
A14: L2-FUL-03 | B14: Checkout with a price hold older than 24h -> blocked, no order created | C14: POST /api/orders POST /api/orders as U1 | D14: HTTP 4xx: must review refreshed prices DB: no order created | E14: Cart PriceLockedAt = NOW - 24h01m (Price Expired) | F14: Passed | G14: 46235 | H14: KhanhTN | I14: Passed | J14: 46236 | K14: KhanhTN | L14: Passed | M14: 46236 | N14: KhanhTN | O14: SRS: FT-01 NAC-03; BV-01; BR-025 | Technique: BVA + Error Path | Negative: Yes | Priority: Critical | Defect: GH-08 | Env: VietTien.API (WebApplicationFactory) + SQL Server · SQL Server 2022 (Testcontainers.MsSql) + Respawn reset
A15: L2-FUL-04 | B15: Tampered cart total in the payload -> 400 and a pricing-bypass alert | C15: POST /api/orders POST /api/orders with tampered body | D15: HTTP 400; security alert persisted/logged ('Pricing Bypass Attempt') DB: no order | E15: Cart true total = 105,000,000 (server-side) Request payload tampered to claim 99,999,999 | F15: Passed | G15: 46235 | H15: KhanhTN | I15: Passed | J15: 46236 | K15: KhanhTN | L15: Passed | M15: 46236 | N15: KhanhTN | O15: SRS: FT-02 NAC-01; BR-005 | Technique: Error Path | Negative: Yes | Priority: Critical | Env: VietTien.API (WebApplicationFactory) + SQL Server · SQL Server 2022 (Testcontainers.MsSql) + Respawn reset
A16: Confirm -> FIFO queue -> Warehouse accept | FT-04 AC-01; BV-03; 4.4.1
A17: L2-FUL-05 | B17: Two confirmed orders reach the warehouse queue in FIFO order | C17: POST /api/orders/{id Sales confirms A then B via POST /api/orders/{id}/confirm; warehouse GETs /api/warehouse/orders | D17: DB: both Confirmed; picking sequence(A) < sequence(B) Warehouse list returns A before B (FIFO) SalesHub/WarehouseHub notifications observed | E17: Orders A (confirmed-eligible, placed 08:00) and B (08:05), both Paid | F17: Passed | G17: 46235 | H17: KhanhTN | I17: Passed | J17: 46236 | K17: KhanhTN | L17: Passed | M17: 46236 | N17: KhanhTN | O17: SRS: FT-05 AC-01; BR-011 | Technique: Happy Path + Workflow | Negative: No | Priority: Critical | Env: VietTien.API (WebApplicationFactory) + SQL Server + SignalR · SQL Server 2022 (Testcontainers.MsSql) + Respawn reset
A18: L2-FUL-06 | B18: Confirming a cancelled order -> 409, no picking ticket | C18: POST /api/orders/C/confirm POST /api/orders/C/confirm | D18: HTTP 409 'order is closed'; DB unchanged; no picking ticket | E18: Order C status = Cancelled | F18: Passed | G18: 46235 | H18: KhanhTN | I18: Passed | J18: 46236 | K18: KhanhTN | L18: Passed | M18: 46236 | N18: KhanhTN | O18: SRS: FT-05 NAC-05 | Technique: Error Path | Negative: Yes | Priority: Critical | Defect: GH-09 | Env: VietTien.API (WebApplicationFactory) + SQL Server · SQL Server 2022 (Testcontainers.MsSql) + Respawn reset
A19: Goods issue & walk-in — atomic stock | FT-04 AC-02, NAC-03; FT-08 NAC-03
A20: L2-FUL-07 | B20: Posting a goods issue decrements stock and logs the transaction atomically | C20: POST /api/warehouse/orders/O1/goods-issue POST /api/warehouse/orders/O1/goods-issue (PostGoodsIssue) | D20: DB: Inventory(P1)=6; StockTransaction rows created; order advances Decrement + status + transaction log committed atomically | E20: Order O1 packed lines: P1 qty=4; Inventory(P1)=10, warehouse staff JWT | F20: Passed | G20: 46235 | H20: KhanhTN | I20: Passed | J20: 46236 | K20: KhanhTN | L20: Passed | M20: 46236 | N20: KhanhTN | O20: SRS: FT-05 AC-05; BV-02; BR-032; BR-034 | Technique: Happy Path + Transaction Boundary | Negative: No | Priority: Critical | Env: VietTien.API (WebApplicationFactory) + SQL Server · SQL Server 2022 (Testcontainers.MsSql) + Respawn reset
A21: L2-FUL-08 | B21: Two walk-in invoices on the last 10 units -> exactly one succeeds | C21: POST /api/orders/place-direct-order Fire both POST /api/orders/place-direct-order simultaneously (barrier) | D21: Exactly ONE invoice succeeds; other gets 'Stock depleted by another transaction...' DB: Inventory(P1) = 0 (never negative); exactly 1 invoice + 1 history append | E21: Inventory(P1) = 10 Two sales staff prepare walk-in invoices for P1 qty=10 each | F21: Passed | G21: 46235 | H21: KhanhTN | I21: Passed | J21: 46236 | K21: KhanhTN | L21: Passed | M21: 46236 | N21: KhanhTN | O21: SRS: FT-05 NAC-01; BV-01; BR-032; NFR-A05 | Technique: Concurrency | Negative: No | Priority: Critical | Env: VietTien.API (WebApplicationFactory) + SQL Server · SQL Server 2022 (Testcontainers.MsSql) + Respawn reset

Sheet L2-Quotation
A2: Feature | B2: L2-Quotation | R2: Passed
A3: Test requirement | B3: Integration test cases for module L2-Quotation — 6 test cases. SRS refs: FT-02 | R3: Failed
A4: Number of TCs | B4: =COUNTA(F11:F18) -> 6 | R4: Pending
A5: Testing Round | B5: Passed | C5: Failed | D5: Pending | E5: N/A | R5: N/A
A6: Round 1 | B6: =COUNTIF($F11:$F18,B5) -> 6 | C6: =COUNTIF($F11:$F18,C5) -> 0 | D6: =COUNTIF($F11:$F18,D5) -> 0 | E6: =COUNTIF($F11:$F18,E5) -> 0
A7: Round 2 | B7: =COUNTIF($I11:$I18,B5) -> 6 | C7: =COUNTIF($I11:$I18,C5) -> 0 | D7: =COUNTIF($I11:$I18,D5) -> 0 | E7: =COUNTIF($I11:$I18,E5) -> 0
A8: Round 3 | B8: =COUNTIF($L11:$L18,B5) -> 6 | C8: =COUNTIF($L11:$L18,C5) -> 0 | D8: =COUNTIF($L11:$L18,D5) -> 0 | E8: =COUNTIF($L11:$L18,E5) -> 0
A10: Test Case ID | B10: Test Case Description | C10: Test Case Procedure | D10: Expected Results | E10: Pre-conditions | F10: Round 1 | G10: Test date | H10: Tester | I10: Round 2 | J10: Test date | K10: Tester | L10: Round 3 | M10: Test date | N10: Tester | O10: Note
A11: Full approval chain | 4.4.3 rows 1-6
A12: L2-QUO-01 | B12: Full quotation approval chain: request -> sales -> manager -> CEO -> customer accept | C12: POST /api/Quotation/from-cart 1) U1 POST /api/Quotation/from-cart 2) S1 pick-up + create version 3) M1 approve 4) C1 approve 5) U1 accept | D12: DB after each step matches 4.4.3: Requested -> Under Sales Review -> Waiting Approval -> Proposed -> Accepted CustomerProfile.NegotiatedPrice persisted Notifications created at each hop | E12: Customer U1 cart total = 120,000,000; no negotiated price Users seeded: sales S1, manager M1, CEO C1 with role JWTs | F12: Passed | G12: 46235 | H12: KhanhTN | I12: Passed | J12: 46236 | K12: KhanhTN | L12: Passed | M12: 46236 | N12: KhanhTN | O12: SRS: FT-02 AC-04; AC-05; BR-027 | Technique: Workflow — Happy Path | Negative: No | Priority: Critical | Env: VietTien.API (WebApplicationFactory) + SQL Server + SignalR (ChatHub) · SQL Server 2022 (Testcontainers.MsSql) + Respawn reset
A13: L2-QUO-02 | B13: Sales role calling the CEO decision endpoint -> 403 | C13: POST /api/Quotation/{id POST /api/Quotation/{id}/ceo-decision as SALES role | D13: HTTP 403; DB status unchanged | E13: Quotation Q1 Waiting Approval; caller = sales staff JWT | F13: Passed | G13: 46235 | H13: KhanhTN | I13: Passed | J13: 46236 | K13: KhanhTN | L13: Passed | M13: 46236 | N13: KhanhTN | O13: SRS: FT-02 NAC-05; NFR-SEC03 | Technique: Error Path | Negative: Yes | Priority: Critical | Env: VietTien.API (WebApplicationFactory) + SQL Server · SQL Server 2022 (Testcontainers.MsSql) + Respawn reset
A14: L2-QUO-03 | B14: Fifth customer rejection -> quotation cancelled, further rounds refused | C14: POST customer-decision (quotation) U1 POST customer-decision {accept:false} (5th rejection) | D14: DB: Q1 = Cancelled; further round rejected with 409/422 Escalation notification created | E14: Q1 Proposed to Customer, negotiation round = 5 | F14: Passed | G14: 46235 | H14: KhanhTN | I14: Passed | J14: 46236 | K14: KhanhTN | L14: Passed | M14: 46236 | N14: KhanhTN | O14: SRS: FT-02 NAC-04 | Technique: BVA | Negative: Yes | Priority: Critical | Env: VietTien.API (WebApplicationFactory) + SQL Server · SQL Server 2022 (Testcontainers.MsSql) + Respawn reset
A15: L2-QUO-04 | B15: Accepted negotiated price applies at 110M but is ignored at 80M | C15: GET /api/orders/checkout-summary U1 builds a NEW cart = 110,000,000 then GET /api/orders/checkout-summary; repeat with cart = 80,000,000 | D15: 110M: negotiated price auto-applied in summary 80M: negotiated price IGNORED — tier-2 discount applied (DC rule) | E15: U1 has Accepted negotiated price from L2-QUO-01 seed | F15: Passed | G15: 46235 | H15: KhanhTN | I15: Passed | J15: 46236 | K15: KhanhTN | L15: Passed | M15: 46236 | N15: KhanhTN | O15: SRS: FT-02 AC-05; NAC-02; BV-01; BR-026 | Technique: Workflow — cross-module | Negative: No | Priority: Critical | Env: VietTien.API (WebApplicationFactory) + SQL Server · SQL Server 2022 (Testcontainers.MsSql) + Respawn reset
A16: Negotiation chat | quotation messaging
A17: L2-QUO-05 | B17: Quotation message is persisted and pushed to the customer in real time | C17: POST /api/Quotation/{id S1 POST /api/Quotation/{id}/messages {content} | D17: DB: ChatMessage row persisted U1's SignalR connection receives the message in real time | E17: Q1 open; U1 (owner) and S1 (assigned) connected to ChatHub | F17: Passed | G17: 46235 | H17: KhanhTN | I17: Passed | J17: 46236 | K17: KhanhTN | L17: Passed | M17: 46236 | N17: KhanhTN | O17: SRS: FT-02 AC-04; BR-020; NFR-P04 | Technique: Happy Path | Negative: No | Priority: High | Env: VietTien.API (WebApplicationFactory) + SQL Server + SignalR (ChatHub) · SQL Server 2022 (Testcontainers.MsSql) + Respawn reset
A18: L2-QUO-06 | B18: Unrelated customer reading quotation messages -> 403/404, nothing leaked | C18: GET /api/Quotation/{id GET /api/Quotation/{id}/messages as U5 | D18: HTTP 403/404; no messages leaked | E18: U5 not related to Q1 (valid JWT, different customer) | F18: Passed | G18: 46235 | H18: KhanhTN | I18: Passed | J18: 46236 | K18: KhanhTN | L18: Passed | M18: 46236 | N18: KhanhTN | O18: SRS: FT-02 NAC-05; NFR-SEC03 | Technique: Error Path | Negative: Yes | Priority: Critical | Env: VietTien.API (WebApplicationFactory) + SQL Server · SQL Server 2022 (Testcontainers.MsSql) + Respawn reset

Sheet L2-Purchasing
A2: Feature | B2: L2-Purchasing | R2: Passed
A3: Test requirement | B3: Integration test cases for module L2-Purchasing — 5 test cases. SRS refs: FT-06 | R3: Failed
A4: Number of TCs | B4: =COUNTA(F11:F16) -> 5 | R4: Pending
A5: Testing Round | B5: Passed | C5: Failed | D5: Pending | E5: N/A | R5: N/A
A6: Round 1 | B6: =COUNTIF($F11:$F16,B5) -> 5 | C6: =COUNTIF($F11:$F16,C5) -> 0 | D6: =COUNTIF($F11:$F16,D5) -> 0 | E6: =COUNTIF($F11:$F16,E5) -> 0
A7: Round 2 | B7: =COUNTIF($I11:$I16,B5) -> 5 | C7: =COUNTIF($I11:$I16,C5) -> 0 | D7: =COUNTIF($I11:$I16,D5) -> 0 | E7: =COUNTIF($I11:$I16,E5) -> 0
A8: Round 3 | B8: =COUNTIF($L11:$L16,B5) -> 5 | C8: =COUNTIF($L11:$L16,C5) -> 0 | D8: =COUNTIF($L11:$L16,D5) -> 0 | E8: =COUNTIF($L11:$L16,E5) -> 0
A10: Test Case ID | B10: Test Case Description | C10: Test Case Procedure | D10: Expected Results | E10: Pre-conditions | F10: Round 1 | G10: Test date | H10: Tester | I10: Round 2 | J10: Test date | K10: Tester | L10: Round 3 | M10: Test date | N10: Tester | O10: Note
A11: PO lifecycle + receipt posting
A12: L2-PUR-01 | B12: PO lifecycle draft -> issued -> sent -> receipt posted increases stock | C12: POST /api/purchase-orders 1) CEO POST /api/purchase-orders (2 lines) 2) POST issue 3) POST send-to-warehouse 4) WH staff POST /api/purchase-orders/{id}/receipts 5) POST /api/purchase-orders/{id}/receipts/{rId}/post (P1 received qty=50) | D12: DB: PO Draft -> Issued -> SentToWarehouse; receipt Posted Inventory(P1,W1) = 60; StockTransaction logged Receipt + inventory in one transaction | E12: CEO user seeded; supplier SUP-1; product P1 Inventory(W1)=10 | F12: Passed | G12: 46235 | H12: KhanhTN | I12: Passed | J12: 46236 | K12: KhanhTN | L12: Passed | M12: 46236 | N12: KhanhTN | O12: SRS: FT-06 AC-01; AC-03; BR-014 | Technique: Workflow — Happy Path | Negative: No | Priority: Critical | Env: VietTien.API (WebApplicationFactory) + SQL Server · SQL Server 2022 (Testcontainers.MsSql) + Respawn reset
A13: L2-PUR-02 | B13: Creating a receipt for a PO still in Draft -> 409 | C13: POST /api/purchase-orders/{id POST /api/purchase-orders/{id}/receipts for PO-2 | D13: HTTP 409; no receipt row created | E13: PO-2 Status = Draft (never sent to warehouse) | F13: Passed | G13: 46235 | H13: KhanhTN | I13: Passed | J13: 46236 | K13: KhanhTN | L13: Passed | M13: 46236 | N13: KhanhTN | O13: SRS: FT-06 NAC-01; BR-014 | Technique: Error Path | Negative: Yes | Priority: Critical | Env: VietTien.API (WebApplicationFactory) + SQL Server · SQL Server 2022 (Testcontainers.MsSql) + Respawn reset
A14: L2-PUR-03 | B14: Posting the same receipt twice -> 409, stock not incremented twice | C14: POST /api/purchase-orders/{id POST /api/purchase-orders/{id}/receipts/{rId}/post for R1 a SECOND time | D14: HTTP 409; Inventory stays 60 — no double increment | E14: Receipt R1 already Posted; Inventory(P1)=60 | F14: Passed | G14: 46235 | H14: KhanhTN | I14: Passed | J14: 46236 | K14: KhanhTN | L14: Passed | M14: 46236 | N14: KhanhTN | O14: SRS: FT-06 NAC-05; BR-029 | Technique: Idempotency | Negative: Yes | Priority: Critical | Env: VietTien.API (WebApplicationFactory) + SQL Server · SQL Server 2022 (Testcontainers.MsSql) + Respawn reset
A15: L2-PUR-04 | B15: Closing a PO with an unresolved discrepancy -> blocked until resolved | C15: POST /api/purchase-orders/{id CEO POST /api/purchase-orders/{id}/close | D15: HTTP 4xx: discrepancy must be resolved first After POST resolve-discrepancy then close -> succeeds | E15: Receipt with qty discrepancy vs PO recorded, unresolved | F15: Passed | G15: 46235 | H15: KhanhTN | I15: Passed | J15: 46236 | K15: KhanhTN | L15: Passed | M15: 46236 | N15: KhanhTN | O15: SRS: FT-06 AC-05; NAC-03; BR-036 | Technique: Error Path | Negative: Yes | Priority: Critical | Defect: GH-03c | Env: VietTien.API (WebApplicationFactory) + SQL Server · SQL Server 2022 (Testcontainers.MsSql) + Respawn reset
A16: L2-PUR-05 | B16: Excel PO import parses the file into draft PO lines | C16: POST /api/purchase-orders/import/excel CEO POST /api/purchase-orders/import/excel (multipart) | D16: DB: PO Draft created with 3 parsed lines matching file values | E16: PO import file: valid Excel with 3 lines | F16: Passed | G16: 46235 | H16: KhanhTN | I16: Passed | J16: 46236 | K16: KhanhTN | L16: Passed | M16: 46236 | N16: KhanhTN | O16: SRS: FT-06 AC-02; NAC-02; BV-03; BR-015 | Technique: Happy Path | Negative: No | Priority: High | Defect: GH-10 | Env: VietTien.API (WebApplicationFactory) + SQL Server · SQL Server 2022 (Testcontainers.MsSql) + Respawn reset

Sheet L2-InventoryTransfer
A2: Feature | B2: L2-InventoryTransfer | R2: Passed
A3: Test requirement | B3: Integration test cases for module L2-InventoryTransfer — 5 test cases. SRS refs: FT-11, FT-12 | R3: Failed
A4: Number of TCs | B4: =COUNTA(F11:F17) -> 5 | R4: Pending
A5: Testing Round | B5: Passed | C5: Failed | D5: Pending | E5: N/A | R5: N/A
A6: Round 1 | B6: =COUNTIF($F11:$F17,B5) -> 5 | C6: =COUNTIF($F11:$F17,C5) -> 0 | D6: =COUNTIF($F11:$F17,D5) -> 0 | E6: =COUNTIF($F11:$F17,E5) -> 0
A7: Round 2 | B7: =COUNTIF($I11:$I17,B5) -> 5 | C7: =COUNTIF($I11:$I17,C5) -> 0 | D7: =COUNTIF($I11:$I17,D5) -> 0 | E7: =COUNTIF($I11:$I17,E5) -> 0
A8: Round 3 | B8: =COUNTIF($L11:$L17,B5) -> 5 | C8: =COUNTIF($L11:$L17,C5) -> 0 | D8: =COUNTIF($L11:$L17,D5) -> 0 | E8: =COUNTIF($L11:$L17,E5) -> 0
A10: Test Case ID | B10: Test Case Description | C10: Test Case Procedure | D10: Expected Results | E10: Pre-conditions | F10: Round 1 | G10: Test date | H10: Tester | I10: Round 2 | J10: Test date | K10: Tester | L10: Round 3 | M10: Test date | N10: Tester | O10: Note
A11: StockTransfer dispatch/receive
A12: L2-TRF-01 | B12: Stock transfer dispatch then receive moves stock between warehouses with a trail | C12: POST dispatch + POST receive (stock transfer) POST dispatch T1; then POST receive T1 {received qty=5} | D12: After dispatch: Inv(P1,W1)=5, T1=Dispatched, StockTransactions logged After receive: Inv(P1,W2)=7, T1=Received smtp4dev captured destination notification | E12: Inventory(P1,W1)=10; Inventory(P1,W2)=2; transfer T1 Draft qty=5 | F12: Passed | G12: 46235 | H12: KhanhTN | I12: Passed | J12: 46236 | K12: KhanhTN | L12: Passed | M12: 46236 | N12: KhanhTN | O12: SRS: FT-11 AC-01; AC-02; BV-02; BR-035 | Technique: Workflow — Happy Path | Negative: No | Priority: Critical | Defect: GH-06 | Env: VietTien.API (WebApplicationFactory) + SQL Server · SQL Server 2022 (Testcontainers.MsSql) + Respawn reset · SMTP -> smtp4dev (transfer notification)
A13: L2-TRF-02 | B13: Receiving more than was dispatched -> rejected / logged as discrepancy | C13: POST receive (stock transfer) POST receive T1 {received qty=6} | D13: HTTP 4xx or discrepancy record; Inv(P1,W2) NOT +6 Source remains consistent | E13: T1 Dispatched qty=5 | F13: Passed | G13: 46235 | H13: KhanhTN | I13: Passed | J13: 46236 | K13: KhanhTN | L13: Passed | M13: 46236 | N13: KhanhTN | O13: SRS: FT-11 NAC-03; BV-02 | Technique: Error Path | Negative: Yes | Priority: Critical | Env: VietTien.API (WebApplicationFactory) + SQL Server · SQL Server 2022 (Testcontainers.MsSql) + Respawn reset
A14: L2-TRF-03 | B14: Transfer dispatch and goods issue on the same stock -> exactly one succeeds | C14: POST dispatch + POST goods-issue (parallel) Fire dispatch and goods-issue simultaneously | D14: Exactly one succeeds; Inventory(P1,W1) = 0 — never negative Loser receives insufficient-stock error | E14: Inventory(P1,W1)=5 Prepared: transfer dispatch qty=5 AND goods issue qty=5 on same stock | F14: Passed | G14: 46235 | H14: KhanhTN | I14: Passed | J14: 46236 | K14: KhanhTN | L14: Passed | M14: 46236 | N14: KhanhTN | O14: SRS: FT-11 NAC-02; BR-032; NFR-A05; NFR-D01 | Technique: Concurrency | Negative: No | Priority: Critical | Env: VietTien.API (WebApplicationFactory) + SQL Server · SQL Server 2022 (Testcontainers.MsSql) + Respawn reset
A15: Inventory adjustment audit
A16: L2-TRF-04 | B16: Inventory adjustment writes an append-only audit row with the delta | C16: PUT /api/inventory/{inventoryId PUT /api/inventory/{inventoryId}/adjust {newQuantity:7, note:'stocktake'} | D16: DB: qty=7; StockTransaction/audit row with delta -3, staff id, note Audit row is append-only (no update of prior rows) | E16: Inventory I1 (P1,W1) qty=10; WH staff JWT | F16: Passed | G16: 46235 | H16: KhanhTN | I16: Passed | J16: 46236 | K16: KhanhTN | L16: Passed | M16: 46236 | N16: KhanhTN | O16: SRS: FT-12 AC-03; BR-044; BR-022 | Technique: Happy Path | Negative: No | Priority: Critical | Defect: GH-12 | Env: VietTien.API (WebApplicationFactory) + SQL Server · SQL Server 2022 (Testcontainers.MsSql) + Respawn reset
A17: L2-TRF-05 | B17: Adjusting inventory to a negative quantity -> rejected, no audit row | C17: PUT /api/inventory/{inventoryId PUT /api/inventory/{inventoryId}/adjust {newQuantity:-1} | D17: HTTP 4xx; qty unchanged; no audit row | E17: Inventory I1 qty=10 | F17: Passed | G17: 46235 | H17: KhanhTN | I17: Passed | J17: 46236 | K17: KhanhTN | L17: Passed | M17: 46236 | N17: KhanhTN | O17: SRS: FT-12 NAC-03; BV-01; BR-032 | Technique: Error Path | Negative: Yes | Priority: Critical | Env: VietTien.API (WebApplicationFactory) + SQL Server · SQL Server 2022 (Testcontainers.MsSql) + Respawn reset

Sheet L2-AuthFlow
A2: Feature | B2: L2-AuthFlow | R2: Passed
A3: Test requirement | B3: Integration test cases for module L2-AuthFlow — 4 test cases. SRS refs: FT-01, NFR-SEC02 | R3: Failed
A4: Number of TCs | B4: =COUNTA(F11:F16) -> 4 | R4: Pending
A5: Testing Round | B5: Passed | C5: Failed | D5: Pending | E5: N/A | R5: N/A
A6: Round 1 | B6: =COUNTIF($F11:$F16,B5) -> 4 | C6: =COUNTIF($F11:$F16,C5) -> 0 | D6: =COUNTIF($F11:$F16,D5) -> 0 | E6: =COUNTIF($F11:$F16,E5) -> 0
A7: Round 2 | B7: =COUNTIF($I11:$I16,B5) -> 4 | C7: =COUNTIF($I11:$I16,C5) -> 0 | D7: =COUNTIF($I11:$I16,D5) -> 0 | E7: =COUNTIF($I11:$I16,E5) -> 0
A8: Round 3 | B8: =COUNTIF($L11:$L16,B5) -> 4 | C8: =COUNTIF($L11:$L16,C5) -> 0 | D8: =COUNTIF($L11:$L16,D5) -> 0 | E8: =COUNTIF($L11:$L16,E5) -> 0
A10: Test Case ID | B10: Test Case Description | C10: Test Case Procedure | D10: Expected Results | E10: Pre-conditions | F10: Round 1 | G10: Test date | H10: Tester | I10: Round 2 | J10: Test date | K10: Tester | L10: Round 3 | M10: Test date | N10: Tester | O10: Note
A11: Register -> verify -> login E2E
A12: L2-AUTH-01 | B12: Register -> OTP email -> verify -> login end to end with a hashed password | C12: POST /api/auth/register 1) POST /api/auth/register 2) read OTP from smtp4dev 3) POST /api/auth/verify-otp 4) POST /api/auth/login | D12: DB: user row with BCrypt hash (!= plaintext); IsVerified=true after step 3 Login returns access + refresh token; refresh persisted | E12: Empty Users table | F12: Passed | G12: 46235 | H12: KhanhTN | I12: Passed | J12: 46236 | K12: KhanhTN | L12: Passed | M12: 46236 | N12: KhanhTN | O12: SRS: FT-01 AC-02; AC-04; BR-023; BR-024; NFR-SEC04 | Technique: Workflow — Happy Path | Negative: No | Priority: Critical | Env: VietTien.API (WebApplicationFactory) + SQL Server · SQL Server 2022 (Testcontainers.MsSql) + Respawn reset · SMTP -> smtp4dev (OTP email capture) WireMock.Net: eSMS API -> 200 (if phone OTP)
A13: L2-AUTH-02 | B13: Login with a wrong password -> no tokens issued or stored | C13: POST /api/auth/login POST /api/auth/login {password:'WRONG'} x1 | D13: HTTP 401-equivalent (Success=false); no tokens in body DB refresh token NOT set | E13: Verified user seeded, hash of 'P@ss123' | F13: Passed | G13: 46235 | H13: KhanhTN | I13: Passed | J13: 46236 | K13: KhanhTN | L13: Passed | M13: 46236 | N13: KhanhTN | O13: SRS: NFR-SEC02 | Technique: Error Path | Negative: Yes | Priority: Critical | Env: VietTien.API (WebApplicationFactory) + SQL Server · SQL Server 2022 (Testcontainers.MsSql) + Respawn reset
A14: Refresh rotation + logout
A15: L2-AUTH-03 | B15: Refresh token rotation invalidates the previous token | C15: POST /api/auth/refresh-token POST /api/auth/refresh-token {RT1}; then POST /api/auth/refresh-token {RT1} AGAIN | D15: First call: new access token + new RT2; DB now stores RT2 Second call with stale RT1: rejected — rotation invalidates old token | E15: Logged-in user with refresh token RT1 in DB | F15: Passed | G15: 46235 | H15: KhanhTN | I15: Passed | J15: 46236 | K15: KhanhTN | L15: Passed | M15: 46236 | N15: KhanhTN | O15: SRS: NFR-SEC02 | Technique: Happy Path + Rotation | Negative: Yes | Priority: Critical | Env: VietTien.API (WebApplicationFactory) + SQL Server · SQL Server 2022 (Testcontainers.MsSql) + Respawn reset
A16: L2-AUTH-04 | B16: Logout clears the refresh token and later refresh is rejected | C16: POST /api/auth/logout POST /api/auth/logout; then POST /api/auth/refresh-token {RT1} | D16: Logout clears DB refresh token Refresh after logout rejected | E16: Logged-in user with refresh token RT1 | F16: Passed | G16: 46235 | H16: KhanhTN | I16: Passed | J16: 46236 | K16: KhanhTN | L16: Passed | M16: 46236 | N16: KhanhTN | O16: SRS: NFR-SEC02 | Technique: Happy Path | Negative: Yes | Priority: High | Env: VietTien.API (WebApplicationFactory) + SQL Server · SQL Server 2022 (Testcontainers.MsSql) + Respawn reset

Sheet L2-Workflows
A2: Feature | B2: L2-Workflows | R2: Passed
A3: Test requirement | B3: Integration test cases for module L2-Workflows — 6 test cases. SRS refs: FT-02, FT-03, FT-05, FT-06, FT-08 | R3: Failed
A4: Number of TCs | B4: =COUNTA(F11:F22) -> 6 | R4: Pending
A5: Testing Round | B5: Passed | C5: Failed | D5: Pending | E5: N/A | R5: N/A
A6: Round 1 | B6: =COUNTIF($F11:$F22,B5) -> 6 | C6: =COUNTIF($F11:$F22,C5) -> 0 | D6: =COUNTIF($F11:$F22,D5) -> 0 | E6: =COUNTIF($F11:$F22,E5) -> 0
A7: Round 2 | B7: =COUNTIF($I11:$I22,B5) -> 6 | C7: =COUNTIF($I11:$I22,C5) -> 0 | D7: =COUNTIF($I11:$I22,D5) -> 0 | E7: =COUNTIF($I11:$I22,E5) -> 0
A8: Round 3 | B8: =COUNTIF($L11:$L22,B5) -> 6 | C8: =COUNTIF($L11:$L22,C5) -> 0 | D8: =COUNTIF($L11:$L22,D5) -> 0 | E8: =COUNTIF($L11:$L22,E5) -> 0
A10: Test Case ID | B10: Test Case Description | C10: Test Case Procedure | D10: Expected Results | E10: Pre-conditions | F10: Round 1 | G10: Test date | H10: Tester | I10: Round 2 | J10: Test date | K10: Tester | L10: Round 3 | M10: Test date | N10: Tester | O10: Note
A11: FLOW-01: SePay payment -> fulfilment eligibility
A12: L2-FLOW-01 | B12: FLOW-01 payment -> confirm -> warehouse queue with notifications at each hop | C12: POST /api/webhooks/sepay-callback POST /api/webhooks/sepay-callback (valid) -> Sales confirms -> Warehouse GET queue | D12: Chain: Paid -> Confirmed -> visible in warehouse FIFO queue SalesHub notified at payment; WarehouseHub at confirm All states consistent in DB at each hop | E12: Order ORD-001 Pending Payment; Sales + Warehouse connected via SignalR test clients | F12: Passed | G12: 46235 | H12: KhanhTN | I12: Passed | J12: 46236 | K12: KhanhTN | L12: Passed | M12: 46236 | N12: KhanhTN | O12: SRS: FT-03 AC-02; FT-05 AC-01; BR-009; BR-011 | Technique: Workflow — Happy Path | Negative: No | Priority: Critical | Env: VietTien.API (WebApplicationFactory) + SQL Server + SignalR · SQL Server 2022 (Testcontainers.MsSql) + Respawn reset
A13: FLOW-02: Full order lifecycle to COD delivery + debt ledger
A14: L2-FLOW-02 | B14: FLOW-02 full lifecycle to COD delivery, stock, SMS and debt ledger | C14: Multi-step: warehouse accept -> goods issue -> schedule delivery -> record delivery result Warehouse accept -> post goods issue -> Sales schedule delivery (V1, Morning) -> record delivery result {collected 5,000,000, signed} | D14: DB checkpoints: Packing -> stock 6 -> In Delivery (SMS fired via WireMock verify) -> Delivered + Paid Debt/credit ledger entry created (CustomerDebt/CreditTransaction) Each transition rejected if attempted out of order | E14: Order Confirmed (COD, total 5,000,000); Inventory(P1)=10; vehicle V1/Morning free | F14: Passed | G14: 46235 | H14: KhanhTN | I14: Passed | J14: 46236 | K14: KhanhTN | L14: Passed | M14: 46236 | N14: KhanhTN | O14: SRS: FT-05 AC-05; FT-07 AC-01; AC-03; AC-04; BR-034; BR-038; BR-039 | Technique: Workflow — Happy Path | Negative: No | Priority: Critical | Defect: GH-03a | Env: VietTien.API (WebApplicationFactory) + SQL Server · SQL Server 2022 (Testcontainers.MsSql) + Respawn reset · WireMock.Net: eSMS -> 200 (delivery SMS) smtp4dev: email capture ⚠ v2.5 DEFECT ID REQUIRED: after the migration patch this case moved from Blocked to FAIL — the cause is no longer the schema but a real business defect, yet the manifest has no defect code assigned. Re-run it, read the red assertion and assign GH-xx (or open a new defect). | ⛔ GH-03a — the chain goes through goods issue, blocked by GoodsIssues missing 8 columns. | ⚠ SCOPE-CHANGE (SRS v2): mandatory POD (photo + signature + timestamp) and a DebtRecord on short collection were added
A15: FLOW-03: Purchasing chain PO -> receipt -> sellable stock
A16: L2-FLOW-03 | B16: FLOW-03 purchasing chain restocks a product until it is purchasable again | C16: GET /api/products/P9 PO issue -> send-to-warehouse -> goods receipt posted -> customer GET /api/products/P9 and add to cart | D16: Inventory(P9) = 50 after posting Storefront shows P9 purchasable; add-to-cart succeeds End-to-end purchasing feeds sales stock | E16: Product P9 Inventory=0 (out of stock on storefront); PO for P9 qty=50 prepared | F16: Passed | G16: 46235 | H16: KhanhTN | I16: Passed | J16: 46236 | K16: KhanhTN | L16: Passed | M16: 46236 | N16: KhanhTN | O16: SRS: FT-06 AC-03; FT-01 AC-01; BR-014 | Technique: Workflow — Happy Path | Negative: No | Priority: Critical | Env: VietTien.API (WebApplicationFactory) + SQL Server · SQL Server 2022 (Testcontainers.MsSql) + Respawn reset
A17: FLOW-04: Shortage -> notify -> restock -> requeue
A18: L2-FLOW-04 | B18: FLOW-04 shortage -> notify -> restock -> order re-enters the queue | C18: POST report-shortage -> stock adjust/receive -> re-queue Warehouse POST report-shortage -> adjust/receive stock to 5 -> re-queue order | D18: DB: Shortage state; Sales notified (SignalR/notification row) After restock: order back to Confirmed and re-enters FIFO queue Packing then completes normally | E18: Order Packing with line P1 qty=5; Inventory(P1)=2 | F18: Passed | G18: 46235 | H18: KhanhTN | I18: Passed | J18: 46236 | K18: KhanhTN | L18: Passed | M18: 46236 | N18: KhanhTN | O18: SRS: FT-05 NAC-04; AC-04 | Technique: Workflow — Error + Recovery | Negative: No | Priority: Critical | Env: VietTien.API (WebApplicationFactory) + SQL Server + SignalR · SQL Server 2022 (Testcontainers.MsSql) + Respawn reset
A19: FLOW-05: Cancel PAID order -> replacement (no refund)
A20: L2-FLOW-05 | B20: FLOW-05 cancel a paid order into a replacement with no refund | C20: POST approve-cancel-and-create-replacement Manager POST approve-cancel-and-create-replacement {new items} | D20: DB: O1 closed; replacement order created referencing O1 NO refund/negative PaymentTransaction created (LI-03) Paid amount linked/credited to replacement | E20: Order O1 Paid (SePay); manager JWT; cancel-paid request submitted | F20: Passed | G20: 46235 | H20: KhanhTN | I20: Passed | J20: 46236 | K20: KhanhTN | L20: Passed | M20: 46236 | N20: KhanhTN | O20: SRS: FT-08 AC-01; AC-02; AC-03; BR-017; BR-041; BR-042 | Technique: Workflow — Compensation | Negative: No | Priority: Critical | Env: VietTien.API (WebApplicationFactory) + SQL Server · SQL Server 2022 (Testcontainers.MsSql) + Respawn reset
A21: FLOW-06: Quotation accepted price applied at next checkout
A22: L2-FLOW-06 | B22: FLOW-06 accepted quotation price applied at the next checkout | C22: POST /api/orders U1 creates new cart = 150,000,000 -> GET checkout summary -> POST /api/orders | D22: Negotiated price auto-applied end-to-end; order total reflects negotiated price Order placed without a new quotation request | E22: Run full L2-QUO-01 chain to Accepted for U1 | F22: Passed | G22: 46235 | H22: KhanhTN | I22: Passed | J22: 46236 | K22: KhanhTN | L22: Passed | M22: 46236 | N22: KhanhTN | O22: SRS: FT-02 AC-05; BR-026 | Technique: Workflow — Happy Path | Negative: No | Priority: Critical | Defect: GH-13 | Env: VietTien.API (WebApplicationFactory) + SQL Server · SQL Server 2022 (Testcontainers.MsSql) + Respawn reset 🔴 GH-13 — THE B2B CHAIN LEADS NOWHERE (functional blocker). Even with Quotation.Status = CustomerAccepted, AcceptedVersionId set and ValidUntil still in the future, checkout-summary still hard-blocks with "orders above 100,000,000 VND please contact a sales rep". In other words there is NO PATH to place an order >= 100M — the whole of FT-02 (the flagship feature) cannot be completed. Suspected link to GH-11 (two endpoints computing the cart total from two different sources). Proposal: let checkout proceed when the customer has a valid accepted quotation. | ⚠ SCOPE-CHANGE (SRS v2): the next order must use the approved quotation version that is still valid, not a stored price

Sheet L2-AfterSalesReturn
A2: Feature | B2: L2-AfterSalesReturn | R2: Passed
A3: Test requirement | B3: Integration test cases for module L2-AfterSalesReturn — 7 test cases. SRS refs: FT-08, NFR-A05 | R3: Failed
A4: Number of TCs | B4: =COUNTA(F11:F19) -> 7 | R4: Pending
A5: Testing Round | B5: Passed | C5: Failed | D5: Pending | E5: N/A | R5: N/A
A6: Round 1 | B6: =COUNTIF($F11:$F19,B5) -> 7 | C6: =COUNTIF($F11:$F19,C5) -> 0 | D6: =COUNTIF($F11:$F19,D5) -> 0 | E6: =COUNTIF($F11:$F19,E5) -> 0
A7: Round 2 | B7: =COUNTIF($I11:$I19,B5) -> 7 | C7: =COUNTIF($I11:$I19,C5) -> 0 | D7: =COUNTIF($I11:$I19,D5) -> 0 | E7: =COUNTIF($I11:$I19,E5) -> 0
A8: Round 3 | B8: =COUNTIF($L11:$L19,B5) -> 7 | C8: =COUNTIF($L11:$L19,C5) -> 0 | D8: =COUNTIF($L11:$L19,D5) -> 0 | E8: =COUNTIF($L11:$L19,E5) -> 0
A10: Test Case ID | B10: Test Case Description | C10: Test Case Procedure | D10: Expected Results | E10: Pre-conditions | F10: Round 1 | G10: Test date | H10: Tester | I10: Round 2 | J10: Test date | K10: Tester | L10: Round 3 | M10: Test date | N10: Tester | O10: Note
A11: Return / exchange and goods pickup | FT-08 AC-05; BR-019; BR-043
A12: L2-RET-01 | B12: Return request -> approval -> pickup -> goods land in quarantine, not sellable | C12: Multi-step: POST return request -> approve -> schedule pickup -> confirm pickup 1. POST create a return/exchange request (2 units) 2. Sales Manager approves 3. POST schedule the pickup 4. POST confirm the goods were collected | D12: After step 2: the request is Approved and a pickup task is created After step 4: goods go to quarantine, RawAvailable(P1) is STILL 10 Every step leaves an audit record | E12: Order O1 Delivered, line P1 delivered 5; available stock of P1 = 10 | F12: Passed | G12: 46235 | H12: KhanhTN | I12: Passed | J12: 46236 | K12: KhanhTN | L12: Passed | M12: 46236 | N12: KhanhTN | O12: SRS: FT-08 AC-05; BR-019 | Technique: Workflow | Negative: No | Priority: Critical | Defect: GH-03b | Env: VietTien.API (WebApplicationFactory) + SQL Server + SignalR · SQL Server 2022 (Testcontainers.MsSql) + Respawn reset
A13: L2-RET-02 | B13: Sales Staff approving a return request -> 403, no pickup task | C13: POST approve return request POST approve request R1 using the Sales Staff JWT | D13: HTTP 403; DB: R1 status unchanged; no pickup task created | E13: Request R1 pending approval; JWT with the Sales Staff role | F13: Passed | G13: 46235 | H13: KhanhTN | I13: Passed | J13: 46236 | K13: KhanhTN | L13: Passed | M13: 46236 | N13: KhanhTN | O13: SRS: FT-08 NAC-05; NFR-SEC03 | Technique: Error Path | Negative: Yes | Priority: Critical | Defect: GH-03b | Env: VietTien.API (WebApplicationFactory) + SQL Server · SQL Server 2022 (Testcontainers.MsSql) + Respawn reset
A14: L2-RET-03 | B14: Return quantity 0 / 5 / 6 against a delivered quantity of 5 | C14: POST create return request POST create a request with qty = [Theory] 0 / 5 / 6 | D14: 0 and 6 are rejected; 5 is accepted No request row exists in the DB for the rejected cases | E14: Order O1 delivered P1 = 5 | F14: Passed | G14: 46235 | H14: KhanhTN | I14: Passed | J14: 46236 | K14: KhanhTN | L14: Passed | M14: 46236 | N14: KhanhTN | O14: SRS: FT-08 BV-03 | Technique: BVA | Negative: Yes | Priority: Critical | Defect: GH-03b | Env: VietTien.API (WebApplicationFactory) + SQL Server · SQL Server 2022 (Testcontainers.MsSql) + Respawn reset
A15: L2-RET-04 | B15: Replacement order pricing: same SKU keeps the original price, new SKU uses the current one | C15: POST create replacement order 1. Create a replacement order with the SAME product P1 2. Create a replacement order swapping to P2 | D15: Same product: the replacement order uses the 50,000 price and creates no receivable Different product: uses the 70,000 price and the difference is recorded explicitly | E15: R1 approved; P1 original price 50,000; P2 current price 70,000 | F15: Passed | G15: 46235 | H15: KhanhTN | I15: Passed | J15: 46236 | K15: KhanhTN | L15: Passed | M15: 46236 | N15: KhanhTN | O15: SRS: FT-08 AC-03; BR-042; BR-043 | Technique: Workflow | Negative: No | Priority: Critical | Defect: GH-03b | Env: VietTien.API (WebApplicationFactory) + SQL Server · SQL Server 2022 (Testcontainers.MsSql) + Respawn reset
A16: Cancelling a paid order | FT-08 AC-01; BR-016; BR-017
A17: L2-RET-05 | B17: Cancel a paid order -> replacement created with no refund transaction | C17: Multi-step: POST cancel paid order -> approve -> create replacement 1. POST a cancellation request for the paid order 2. Sales Manager approves 3. Create the replacement order | D17: DB: Payment REMAINS PAID; NO refund transaction is created The original order is closed and the replacement references it | E17: Order O1 already PAID via SePay and not yet delivered | F17: Passed | G17: 46235 | H17: KhanhTN | I17: Passed | J17: 46236 | K17: KhanhTN | L17: Passed | M17: 46236 | N17: KhanhTN | O17: SRS: FT-08 AC-01; BR-017 | Technique: Workflow | Negative: No | Priority: Critical | Env: VietTien.API (WebApplicationFactory) + SQL Server · SQL Server 2022 (Testcontainers.MsSql) + Respawn reset
A18: L2-RET-06 | B18: Cancellation request on an order In Delivery -> 409 | C18: POST cancel paid order request POST a cancellation request | D18: HTTP 409; DB: no cancellation request created; order status unchanged | E18: Order O1 is In Delivery | F18: Passed | G18: 46235 | H18: KhanhTN | I18: Passed | J18: 46236 | K18: KhanhTN | L18: Passed | M18: 46236 | N18: KhanhTN | O18: SRS: FT-08 NAC-05; 4.4.1 | Technique: Error Path | Negative: Yes | Priority: Critical | Defect: GH-14 | Env: VietTien.API (WebApplicationFactory) + SQL Server · SQL Server 2022 (Testcontainers.MsSql) + Respawn reset
