Workbook

Sheet Introduction
B1: Level 4 — E2E Test | Test Case Specification Template
B2: Primary tool: Playwright (TypeScript) · Trình duyệt thật, không mock · Môi trường staging: ASP.NET Core 8 + SQL Server 2022 + React/Vite
B4: 🎯 Purpose — What does this test level verify?
B5: Verify that real users can complete their goals using the full application — from browser through UI, API, and database — with nothing mocked. Key question: 'Can the user successfully accomplish what they need to do?'
B7: ✅ In Scope
B8: • Full stack: Browser → API ASP.NET Core → SQL Server 2022 → SignalR/Hangfire • Nothing mocked — all systems real (or sandboxed: payment gateway, courier API) • User journeys: complete flows from login to goal completion • RBAC on UI: correct menu items, buttons, and data visible per role • Session management: login, logout, token refresh, multiple tabs • Browser behavior: navigation, form validation, error messages, toasts
B10: ❌ Out of Scope
B11: • Internal method logic (→ L1) • DB/queue integration (→ L2) • API contract details and HTTP headers (→ L3) • Performance under load (→ L3) • Security attack vectors (→ L3) • Scenarios that do not require a browser (→ L3-APIFlows)
B13: 🔬 Coverage Techniques
B14: Critical Path (Smoke): Happy path only. Fast (< 10 min total). Run after every deploy to verify system is not dead-on-arrival. User Journey (Regression): Full flow including important error paths. Run before merge to main. Covers AC-xx and key NAC-xx from SRS. Permission Boundary: Verify each role sees exactly what they should — correct menu items, buttons visible/hidden, 403 on forbidden pages. Session Management: Login → action → logout → back button. Silent refresh during active session. Multiple tabs consistency. Negative UI: Verify error messages, inline validation, disabled buttons — that the UI communicates failures clearly (NFR-U03).
B16: 🛠️ Primary Tool
B17: Playwright (TypeScript) · Trình duyệt thật, không mock · Môi trường staging: ASP.NET Core 8 + SQL Server 2022 + React/Vite
B19: 📋 Column Definitions — How to fill each column
B20: Test ID | C20: Format: L4-[SheetAbbr]-[NN] Examples: L4-CP-01, L4-F01-03, L4-PERM-02, L4-SESS-01
B21: Coverage Technique | C21: Values: Critical Path, User Journey - Happy, User Journey - Error, Permission Boundary, Session Management, Negative UI
B22: Actor (Role) | C22: The role performing the test. Values: Customer, Warehouse Staff, Manager, Admin For multi-user tests: list both (e.g. Staff A + Staff B)
B23: Entry Point (URL / Page) | C23: Starting URL or page name from Screen Design Spec. Example: /login (P-00) Example: /orders (P-02a Order Queue)
B24: Precondition (DB + Auth + Sandbox) | C24: Everything needed before the first browser action: • User account and credentials • DB state (orders, stock, etc.) • Sandbox config (payment: succeed/fail; courier: respond/timeout)
B25: Test Steps (Browser Actions) | C25: Numbered browser actions: 1. Navigate to [URL] 2. Click [element name] 3. Type [value] in [field] 4. Wait for [condition] 5. Assert [visible state] Each step should be a discrete user action.
B26: Expected UI Result | C26: What the user SEES in the browser: • Visible headings, text, badges • Button enabled/disabled state • Toast messages • Page navigation (redirect to /X) • DB side-effect (optional — query to verify)
B27: Negative? | C27: Yes = test expects an error, blocked action, or rejection shown in UI.
B28: Status | C28: Not Run / Pass / Fail / Blocked / Skip
B29: Defect ID | C29: Issue tracker reference when Status = Fail.
B30: Notes | C30: Playwright selector hints, test data file, known flakiness, sandbox config.
B32: 📝 How to Fill — Step by step
B33: 1. For L4-CriticalPaths: identify the minimum set of happy paths that verify the system is usable. Max 6 cases, < 2 min each.
B34: 2. For L4-UserJourneys: take each Screen Flow (F-01..F-05) and write Happy + key Error paths. Verify side effects (DB state, toast messages).
B35: 3. For L4-Permissions: for each role, list pages and buttons they CANNOT access. Write one test per forbidden action.
B36: 4. For L4-SessionManagement: cover login per role, logout + back button, silent refresh (wait 16 min), account lock UI message.
B37: 5. Check if the test actually requires a browser. If it only needs HTTP calls, move to L3-APIFlows.
B38: 6. Write Precondition explicitly — another developer must be able to run this test from scratch.
B39: 7. Use Playwright page.waitForSelector() or expect(locator).toBeVisible() — not sleep().
B40: 8. Run tests against staging → update Status → add Defect ID if Fail.
B42: 🎨 Priority & Status Legend
B43: P1 — Critical | C43: Must pass before any release. Blocking.
B44: P2 — High | C44: Should pass. Non-blocking but important.
B45: P3 — Medium | C45: Nice to have in this cycle.
B47: Not Run
B48: Pass
B49: Fail
...

Sheet TestCase List
A1: TestCase List | L4 E2E Test index — SRS v2.0.0 | v1.3 đóng khoảng trống truy vết AC/NAC
A3: Total test cases | B3: =COUNTA(A7:A798) -> 47 | C3: P1 | D3: =COUNTIF(E7:E798,"P1") -> 35 | E3: P2 | F3: =COUNTIF(E7:E798,"P2") -> 12 | G3: P3 | H3: =COUNTIF(E7:E798,"P3") -> 0
A4: Negative tests | B4: =COUNTIF(F7:F798,"Yes") -> 14 | C4: Pass | D4: =COUNTIF(G7:G798,"Pass") -> 36 | E4: Fail | F4: =COUNTIF(G7:G798,"Fail") -> 3 | G4: Not Run | H4: =COUNTIF(G7:G798,"Not Run") -> 0
A6: Test ID | B6: Sheet | C6: Nhóm / Block | D6: SRS Reference | E6: Priority | F6: Negative? | G6: Status (live link) | H6: Defect ID (live link)
A7: L4-CP-01 | B7: L4-CriticalPaths | C7: Critical Paths — Smoke suite | D7: FT-01 AC-05; FT-03 AC-04; SC-01 | E7: P1 | F7: No | G7: ='L4-CriticalPaths'!L6 -> Pass | H7: ='L4-CriticalPaths'!M6
A8: L4-CP-02 | B8: L4-CriticalPaths | C8: Critical Paths — Smoke suite | D8: FT-03 AC-02; BR-009 | E8: P1 | F8: No | G8: ='L4-CriticalPaths'!L7 -> Pass | H8: ='L4-CriticalPaths'!M7
A9: L4-CP-03 | B9: L4-CriticalPaths | C9: Critical Paths — Smoke suite | D9: FT-05 AC-01; AC-04; BR-011 | E9: P1 | F9: No | G9: ='L4-CriticalPaths'!L8 -> Pass | H9: ='L4-CriticalPaths'!M8
A10: L4-CP-04 | B10: L4-CriticalPaths | C10: Critical Paths — Smoke suite | D10: FT-05 AC-05; BR-034 | E10: P1 | F10: No | G10: ='L4-CriticalPaths'!L9 -> Fail | H10: ='L4-CriticalPaths'!M9 -> DEF-L4-001
A11: L4-CP-05 | B11: L4-CriticalPaths | C11: Critical Paths — Smoke suite | D11: FT-07 AC-01; AC-03; BR-038 | E11: P1 | F11: No | G11: ='L4-CriticalPaths'!L10 -> Blocked | H11: ='L4-CriticalPaths'!M10 -> DEF-L4-002
A12: L4-CP-06 | B12: L4-CriticalPaths | C12: Critical Paths — Smoke suite | D12: FT-01 AC-01; NFR-U03 | E12: P1 | F12: No | G12: ='L4-CriticalPaths'!L11 -> Pass | H12: ='L4-CriticalPaths'!M11
A13: L4-UJ-01 | B13: L4-UserJourneys | C13: SC-01 — Đăng ký, mua hàng, định giá và báo giá | D13: FT-01 AC-02; AC-04; BR-023; BR-024; SC-01 | E13: P1 | F13: No | G13: ='L4-UserJourneys'!L6 -> Pass | H13: ='L4-UserJourneys'!M6
A14: L4-UJ-02 | B14: L4-UserJourneys | C14: SC-01 — Đăng ký, mua hàng, định giá và báo giá | D14: FT-02 AC-01; BV-01; BR-006; SC-01 | E14: P1 | F14: No | G14: ='L4-UserJourneys'!L7 -> Pass | H14: ='L4-UserJourneys'!M7
A15: L4-UJ-03 | B15: L4-UserJourneys | C15: SC-01 — Đăng ký, mua hàng, định giá và báo giá | D15: FT-02 AC-04; AC-05; BR-027; SC-01 | E15: P1 | F15: No | G15: ='L4-UserJourneys'!L8 -> Pass | H15: ='L4-UserJourneys'!M8
A16: L4-UJ-14 | B16: L4-UserJourneys | C16: SC-01 — Đăng ký, mua hàng, định giá và báo giá | D16: FT-01 AC-03; BV-03; NAC-05; BR-028; SC-01 | E16: P2 | F16: No | G16: ='L4-UserJourneys'!L9 -> Pass | H16: ='L4-UserJourneys'!M9
A17: L4-UJ-04 | B17: L4-UserJourneys | C17: SC-02 — Thanh toán, phân công Sales và thực hiện đơn | D17: FT-04 AC-02; AC-04; BR-002; SC-02 | E17: P1 | F17: No | G17: ='L4-UserJourneys'!L11 -> Pass | H17: ='L4-UserJourneys'!M11
A18: L4-UJ-05 | B18: L4-UserJourneys | C18: SC-02 — Thanh toán, phân công Sales và thực hiện đơn | D18: FT-03 AC-03; NAC-03; BR-016; SC-02 | E18: P1 | F18: No | G18: ='L4-UserJourneys'!L12 -> Pass | H18: ='L4-UserJourneys'!M12
A19: L4-UJ-06 | B19: L4-UserJourneys | C19: SC-03 — Giao hàng, thu COD và hậu mãi | D19: FT-07 AC-04; NAC-04; BV-02; BR-039; SC-03 | E19: P1 | F19: No | G19: ='L4-UserJourneys'!L14 -> Blocked | H19: ='L4-UserJourneys'!M14 -> DEF-L4-002
A20: L4-UJ-07 | B20: L4-UserJourneys | C20: SC-03 — Giao hàng, thu COD và hậu mãi | D20: FT-08 AC-01; AC-02; AC-03; BR-017; SC-03 | E20: P1 | F20: No | G20: ='L4-UserJourneys'!L15 -> Pass | H20: ='L4-UserJourneys'!M15
A21: L4-UJ-08 | B21: L4-UserJourneys | C21: SC-03 — Giao hàng, thu COD và hậu mãi | D21: FT-08 AC-05; BR-019; SC-03 | E21: P2 | F21: No | G21: ='L4-UserJourneys'!L16 -> Pass | H21: ='L4-UserJourneys'!M16
A22: L4-UJ-09 | B22: L4-UserJourneys | C22: SC-06 — Mua hàng, chuyển kho và kiểm soát tồn kho | D22: FT-06 AC-01; AC-03; AC-05; BR-014; SC-06 | E22: P1 | F22: No | G22: ='L4-UserJourneys'!L18 -> Pass | H22: ='L4-UserJourneys'!M18
A23: L4-UJ-10 | B23: L4-UserJourneys | C23: SC-06 — Mua hàng, chuyển kho và kiểm soát tồn kho | D23: FT-11 AC-01; AC-02; AC-03; BR-035; SC-06 | E23: P1 | F23: No | G23: ='L4-UserJourneys'!L19 -> Pass | H23: ='L4-UserJourneys'!M19
A24: L4-UJ-11 | B24: L4-UserJourneys | C24: SC-06 — Mua hàng, chuyển kho và kiểm soát tồn kho | D24: FT-12 AC-01; AC-02; AC-03; BR-044; SC-06 | E24: P1 | F24: No | G24: ='L4-UserJourneys'!L20 -> Blocked | H24: ='L4-UserJourneys'!M20 -> DEF-L4-003
A25: L4-UJ-12 | B25: L4-UserJourneys | C25: SC-06 — Mua hàng, chuyển kho và kiểm soát tồn kho | D25: FT-12 AC-05; BR-045; SC-06 | E25: P2 | F25: No | G25: ='L4-UserJourneys'!L21 -> Pass | H25: ='L4-UserJourneys'!M21
A26: L4-UJ-13 | B26: L4-UserJourneys | C26: SC-06 — Mua hàng, chuyển kho và kiểm soát tồn kho | D26: FT-12 AC-04; BV-03; BR-049; SC-06 | E26: P2 | F26: No | G26: ='L4-UserJourneys'!L22 -> Blocked | H26: ='L4-UserJourneys'!M22 -> DEF-L4-003
A27: L4-PM-01 | B27: L4-Permissions | C27: Chặn truy cập theo vai trò (kiểm tra ở UI, không chỉ ẩn nút) | D27: NFR-SEC03; FT-01 NAC-05 | E27: P1 | F27: Yes | G27: ='L4-Permissions'!L6 -> Pass | H27: ='L4-Permissions'!M6
A28: L4-PM-02 | B28: L4-Permissions | C28: Chặn truy cập theo vai trò (kiểm tra ở UI, không chỉ ẩn nút) | D28: NFR-SEC03 | E28: P1 | F28: Yes | G28: ='L4-Permissions'!L7 -> Pass | H28: ='L4-Permissions'!M7
A29: L4-PM-03 | B29: L4-Permissions | C29: Chặn truy cập theo vai trò (kiểm tra ở UI, không chỉ ẩn nút) | D29: NFR-SEC03; BR-027 | E29: P1 | F29: Yes | G29: ='L4-Permissions'!L8 -> Pass | H29: ='L4-Permissions'!M8
A30: L4-PM-04 | B30: L4-Permissions | C30: Chặn truy cập theo vai trò (kiểm tra ở UI, không chỉ ẩn nút) | D30: NFR-SEC03; FT-09 NAC-02 | E30: P1 | F30: Yes | G30: ='L4-Permissions'!L9 -> Fail | H30: ='L4-Permissions'!M9 -> DEF-L4-005
A31: L4-PM-05 | B31: L4-Permissions | C31: Chặn truy cập theo vai trò (kiểm tra ở UI, không chỉ ẩn nút) | D31: NFR-SEC03; FT-04 NAC-04 | E31: P1 | F31: Yes | G31: ='L4-Permissions'!L10 -> Pass | H31: ='L4-Permissions'!M10
A32: L4-PM-06 | B32: L4-Permissions | C32: Chặn truy cập theo vai trò (kiểm tra ở UI, không chỉ ẩn nút) | D32: NFR-SEC03; FT-05 NAC-05 | E32: P1 | F32: Yes | G32: ='L4-Permissions'!L11 -> Pass | H32: ='L4-Permissions'!M11
A33: L4-PM-07 | B33: L4-Permissions | C33: Chặn truy cập theo vai trò (kiểm tra ở UI, không chỉ ẩn nút) | D33: NFR-SEC03; FT-01 NAC-05 | E33: P1 | F33: Yes | G33: ='L4-Permissions'!L12 -> Pass | H33: ='L4-Permissions'!M12
A34: L4-SM-01 | B34: L4-SessionManagement | C34: Vòng đời phiên | D34: NFR-SEC02 | E34: P1 | F34: No | G34: ='L4-SessionManagement'!L6 -> Pass | H34: ='L4-SessionManagement'!M6
A35: L4-SM-02 | B35: L4-SessionManagement | C35: Vòng đời phiên | D35: NFR-SEC02 | E35: P1 | F35: Yes | G35: ='L4-SessionManagement'!L7 -> Pass | H35: ='L4-SessionManagement'!M7
A36: L4-SM-03 | B36: L4-SessionManagement | C36: Vòng đời phiên | D36: NFR-SEC02 | E36: P2 | F36: Yes | G36: ='L4-SessionManagement'!L8 -> Pass | H36: ='L4-SessionManagement'!M8
A37: L4-SM-04 | B37: L4-SessionManagement | C37: Vòng đời phiên | D37: FT-01 AC-05; BR-025 | E37: P1 | F37: No | G37: ='L4-SessionManagement'!L9 -> Pass | H37: ='L4-SessionManagement'!M9
A38: L4-SM-05 | B38: L4-SessionManagement | C38: Vòng đời phiên | D38: FT-01 NAC-03; BV-01; BR-025 | E38: P1 | F38: Yes | G38: ='L4-SessionManagement'!L10 -> Fail | H38: ='L4-SessionManagement'!M10 -> DEF-L4-007
A39: L4-RS-01 | B39: L4-Responsive (Optional) | C39: Giao diện đáp ứng và ngôn ngữ | D39: NFR-U01 | E39: P2 | F39: No | G39: ='L4-Responsive (Optional)'!L6 -> Pass | H39: ='L4-Responsive (Optional)'!M6
A40: L4-RS-02 | B40: L4-Responsive (Optional) | C40: Giao diện đáp ứng và ngôn ngữ | D40: NFR-U01 | E40: P2 | F40: No | G40: ='L4-Responsive (Optional)'!L7 -> Pass | H40: ='L4-Responsive (Optional)'!M7
A41: L4-RS-03 | B41: L4-Responsive (Optional) | C41: Giao diện đáp ứng và ngôn ngữ | D41: NFR-U02 | E41: P2 | F41: No | G41: ='L4-Responsive (Optional)'!L8 -> Pass | H41: ='L4-Responsive (Optional)'!M8
A42: L4-RS-04 | B42: L4-Responsive (Optional) | C42: Giao diện đáp ứng và ngôn ngữ | D42: NFR-U03 | E42: P2 | F42: No | G42: ='L4-Responsive (Optional)'!L9 -> Pass | H42: ='L4-Responsive (Optional)'!M9
...

Sheet L4-CriticalPaths
A1: L4-CriticalPaths | Smoke test — chạy sau mỗi lần deploy | 6 case | Mục tiêu < 12 phút
A2: HOW TO USE: (1) Đọc Introduction (2) Đối chiếu route + data-testid với FE trước khi viết script (3) Chạy npx playwright test trên staging (4) Cập nhật Status (5) Ghi Defect ID khi Fail
A4: Test ID | B4: Coverage Technique | C4: SRS Reference | D4: Feature | E4: Priority | F4: Actor (Role) | G4: Entry Point (URL / Page) | H4: Precondition (DB + Auth + Sandbox) | I4: Test Steps (Browser Actions) | J4: Expected UI Result | K4: Negative? | L4: Status | M4: Defect ID | N4: Notes
A5: ▶ Critical Paths — Smoke suite | Chỉ happy path | Chạy sau mỗi deploy
A6: L4-CP-01 | B6: Critical Path | C6: FT-01 AC-05; FT-03 AC-04; SC-01 | D6: FT-01, FT-03 | E6: P1 | F6: Customer | G6: /login → /products → /cart → /checkout | H6: TK: customer1@viettien.test / Test@123 (đã verify) SKU-001 còn tồn >= 2 Giỏ hàng trống trước khi chạy | I6: 1. Vào /login, nhập email + mật khẩu, bấm Đăng nhập 2. Vào /products, mở SKU-001, chọn số lượng 1, bấm Thêm vào giỏ 3. Mở /cart, kiểm tra 1 dòng, bấm Thanh toán 4. Chọn địa chỉ giao, chọn COD, bấm Đặt hàng | J6: Trang xác nhận đơn hiển thị Mã đơn hiện đúng định dạng Trạng thái hiển thị 'Chờ xác nhận' Email xác nhận nhận được (smtp4dev/mailbox test) | K6: No | L6: Pass
A7: L4-CP-02 | B7: Critical Path | C7: FT-03 AC-02; BR-009 | D7: FT-03 | E7: P1 | F7: Customer + SePay sandbox | G7: /checkout → màn hình QR | H7: Đơn ORD-SMOKE ở trạng thái chờ thanh toán SePay sandbox sẵn sàng | I7: 1. Chọn thanh toán SePay ở bước cuối checkout 2. Quan sát mã QR + mã tham chiếu + đồng hồ đếm ngược 3. Kích hoạt webhook sandbox với đúng số tiền 4. Chờ giao diện tự cập nhật | J7: QR + mã tham chiếu hiển thị, đếm ngược 15 phút chạy Sau webhook: trạng thái đổi sang 'Đã thanh toán' KHÔNG cần tải lại trang (SignalR) | K7: No | L7: Pass
A8: L4-CP-03 | B8: Critical Path | C8: FT-05 AC-01; AC-04; BR-011 | D8: FT-05 | E8: P1 | F8: Warehouse Staff | G8: /warehouse/fulfillment/orders | H8: TK: warehouse1@viettien.test Đơn ORD-SMOKE đã CONFIRMED | I8: 1. Đăng nhập vai trò Warehouse Staff 2. Mở danh sách đơn cần soạn 3. Nhận đơn ORD-SMOKE 4. Nhập số lượng soạn thực tế và số kiện | J8: Đơn xuất hiện trong hàng đợi Sau khi nhận: trạng thái đổi sang đang soạn, phiếu khoá theo nhân viên Lưu số lượng + số kiện thành công | K8: No | L8: Pass
A9: L4-CP-04 | B9: Critical Path | C9: FT-05 AC-05; BR-034 | D9: FT-05 | E9: P1 | F9: Warehouse Staff + Sales Staff | G9: /warehouse/fulfillment/handover → /warehouse/fulfillment/goods-issue | H9: Đơn ORD-SMOKE đã soạn xong, N kiện 2 tài khoản: kho + sales cùng truy cập | I9: 1. Nhân viên kho xác nhận N kiện + đính kèm bằng chứng 2. Nhân viên Sales xác nhận đúng N kiện 3. Quan sát trạng thái bàn giao | J9: Chỉ khi CẢ HAI xác nhận cùng số kiện thì mới cho phép xuất kho Biên bản bàn giao lưu đủ 2 danh tính + thời điểm | K9: No | L9: Fail | M9: DEF-L4-001 | N9: sales-confirm tra 403 cho tai khoan SalesStaff. HandoverController.cs:35-36 khai role "Sales" — gia tri khong ton tai trong enum SystemRole -> khong the du 2 chu ky.
A10: L4-CP-05 | B10: Critical Path | C10: FT-07 AC-01; AC-03; BR-038 | D10: FT-07 | E10: P1 | F10: Sales Staff | G10: /sales/delivery/arrangement → /sales/delivery | H10: Đơn đã bàn giao Xe 1 còn trống ca Morning | I10: 1. Mở màn hình sắp xếp giao hàng, chọn xe 1 + ca Morning + ngày 2. Bắt đầu chuyến 3. Ghi nhận giao thành công: tải ảnh + chữ ký khách | J10: Đơn chuyển 'Đang giao' Không cho lưu khi thiếu ảnh hoặc chữ ký Sau khi đủ bằng chứng: trạng thái 'Đã giao' | K10: No | L10: Blocked | M10: DEF-L4-002 | N10: GET /api/delivery/trips -> 404. Module chuyen giao hang chua trien khai (trung DEF-L3-004).
A11: L4-CP-06 | B11: Critical Path | C11: FT-01 AC-01; NFR-U03 | D11: FT-01 | E11: P1 | F11: Guest | G11: / (trang chủ) | H11: Không đăng nhập Có ít nhất 10 sản phẩm Active | I11: 1. Mở trang chủ 2. Tìm kiếm theo từ khoá 3. Lọc theo danh mục, chuyển trang 4. Mở chi tiết 1 sản phẩm | J11: Trang tải, hiển thị sản phẩm Kết quả tìm/lọc/phân trang đúng Sản phẩm ngừng kinh doanh KHÔNG xuất hiện | K11: No | L11: Pass
A12: ▶ Template Row — copy khi thêm case mới
A13: L4-XX-[NN] | B13: [Critical Path | User Journey | Permission | Session | Responsive] | C13: [FT-xx AC/NAC/BV-xx; BR-xxx; SC-xx] | D13: [FT-xx] | E13: P2 | F13: [Vai trò] | G13: [/route hoặc tên màn hình] | H13: [TK test + trạng thái DB + sandbox] | I13: 1. ... 2. ... 3. ... | J13: [Người dùng THẤY gì trên màn hình] | K13: No | L13: Not Run

Sheet L4-UserJourneys
A1: L4-UserJourneys | Hành trình nghiệp vụ đầy đủ theo SC-01..SC-06 của SRS v2
A2: HOW TO USE: (1) Đọc Introduction (2) Đối chiếu route + data-testid với FE trước khi viết script (3) Chạy npx playwright test trên staging (4) Cập nhật Status (5) Ghi Defect ID khi Fail
A4: Test ID | B4: Coverage Technique | C4: SRS Reference | D4: Feature | E4: Priority | F4: Actor (Role) | G4: Entry Point (URL / Page) | H4: Precondition (DB + Auth + Sandbox) | I4: Test Steps (Browser Actions) | J4: Expected UI Result | K4: Negative? | L4: Status | M4: Defect ID | N4: Notes
A5: ▶ SC-01 — Đăng ký, mua hàng, định giá và báo giá
A6: L4-UJ-01 | B6: User Journey | C6: FT-01 AC-02; AC-04; BR-023; BR-024; SC-01 | D6: FT-01 | E6: P1 | F6: Guest → Customer | G6: /register → /verify-otp → /profile | H6: Email chưa tồn tại trong hệ thống SMS sandbox bật Hộp thư test truy cập được | I6: 1. Đăng ký bằng email mới 2. Mở email, bấm link xác thực 3. Đăng nhập, vào hồ sơ 4. Thêm địa chỉ giao hàng, đặt làm mặc định 5. Xác thực số điện thoại bằng OTP | J6: Tài khoản chỉ hoạt động SAU khi xác thực email Chỉ 1 địa chỉ mặc định tồn tại OTP sai/hết hạn báo lỗi rõ ràng bằng tiếng Việt | K6: No | L6: Pass
A7: L4-UJ-02 | B7: User Journey | C7: FT-02 AC-01; BV-01; BR-006; SC-01 | D7: FT-02 | E7: P1 | F7: Customer | G7: /products → /cart | H7: Có SKU đủ tồn để đạt từng mốc giá | I7: 1. Thêm hàng cho tới khi tổng < 10.000.000đ, xem đơn giá 2. Thêm tiếp để tổng đạt 10.000.000đ 3. Thêm tiếp để tổng đạt 100.000.000đ | J7: < 10 triệu: giá niêm yết >= 10 triệu: hiển thị chiết khấu bậc >= 100 triệu: ẨN nút thanh toán, hiện 'Yêu cầu báo giá' | K7: No | L7: Pass
A8: L4-UJ-03 | B8: User Journey | C8: FT-02 AC-04; AC-05; BR-027; SC-01 | D8: FT-02 | E8: P1 | F8: Customer + Sales Staff + Sales Manager + CEO | G8: /negotiations (khách) → /sales/negotiation → /sales-manager/manager-negotiation → CEOPortal tab "price-negotiation" | H8: Giỏ 120.000.000đ 4 tài khoản 4 vai trò | I8: 1. Khách gửi yêu cầu báo giá 2. Sales nhận việc, trao đổi tin nhắn, gửi giá đề xuất 3. Sales Manager duyệt 4. CEO duyệt lần cuối 5. Khách chấp nhận và đặt hàng | J8: Mỗi vai trò chỉ thấy đúng phần việc của mình Khách KHÔNG chấp nhận được version chưa qua đủ 2 cấp Sau khi chấp nhận: checkout dùng đúng giá đã duyệt | K8: No | L8: Pass
A9: L4-UJ-14 | B9: User Journey | C9: FT-01 AC-03; BV-03; NAC-05; BR-028; SC-01 | D9: FT-01 | E9: P2 | F9: Customer | G9: /profile/addresses → /checkout → /profile/orders/:orderId | H9: Khách đã có 1 địa chỉ mặc định và 1 đơn hàng cũ dùng địa chỉ đó | I9: 1. Thêm địa chỉ mới và đặt làm mặc định 2. Thử xoá địa chỉ đã dùng cho đơn cũ 3. Đặt đơn mới, sau đó sửa lại địa chỉ và thông tin VAT trong hồ sơ 4. Mở lại chi tiết đơn vừa đặt | J9: Luôn chỉ có ĐÚNG 1 địa chỉ mặc định Không xoá cứng được địa chỉ đã dùng — hệ thống giải thích và chỉ cho ngừng sử dụng Địa chỉ giao và thông tin VAT trên đơn đã đặt GIỮ NGUYÊN dù hồ sơ đã đổi | K9: No | L9: Pass
A10: ▶ SC-02 — Thanh toán, phân công Sales và thực hiện đơn
A11: L4-UJ-04 | B11: User Journey | C11: FT-04 AC-02; AC-04; BR-002; SC-02 | D11: FT-04 | E11: P1 | F11: Customer + Sales Manager | G11: /sales-manager/round-robin · /sales/change-requests | H11: Có >= 2 Sales Staff đang hoạt động | I11: 1. Đăng ký 3 khách mới liên tiếp 2. Sales Manager mở màn hình round-robin xem phân công 3. Một khách gửi yêu cầu đổi Sales kèm lý do 4. Sales Manager duyệt | J11: 3 khách được chia luân phiên, không trùng, không bỏ sót Khách chỉ tạo được 1 yêu cầu đang mở Sau khi duyệt: chủ sở hữu mới, đơn CŨ vẫn giữ tên Sales cũ | K11: No | L11: Pass
A12: L4-UJ-05 | B12: User Journey | C12: FT-03 AC-03; NAC-03; BR-016; SC-02 | D12: FT-03 | E12: P1 | F12: Sales Manager | G12: /sales-manager/sepay-exceptions | H12: Có giao dịch SePay không khớp/đến muộn nằm trong danh sách ngoại lệ | I12: 1. Mở màn hình ngoại lệ SePay 2. Xem bằng chứng giao dịch 3. Thử phân bổ lại vào đơn đúng 4. Thử xác nhận thủ công mà KHÔNG nhập lý do/bằng chứng | J12: Danh sách chỉ hiện ngoại lệ chưa xử lý Xác nhận thủ công bị chặn khi thiếu bằng chứng Sau khi xử lý: đơn rời khỏi danh sách ngoại lệ | K12: No | L12: Pass
A13: ▶ SC-03 — Giao hàng, thu COD và hậu mãi
A14: L4-UJ-06 | B14: User Journey | C14: FT-07 AC-04; NAC-04; BV-02; BR-039; SC-03 | D14: FT-07 | E14: P1 | F14: Sales Staff | G14: /sales/delivery/collection | H14: Đơn A: COD, còn nợ 5.000.000đ Đơn B: đã thanh toán SePay | I14: 1. Mở đơn A, nhập số tiền thu = 3.000.000đ 2. Quan sát phần còn nợ 3. Mở đơn B, thử nhập tiền thu | J14: Đơn A: ghi đúng 3.000.000đ + tạo công nợ 2.000.000đ Đơn B: hiển thị cảnh báo 'ĐÃ THANH TOÁN — KHÔNG THU TIỀN', ô nhập bị khoá | K14: No | L14: Blocked | M14: DEF-L4-002 | N14: GET /api/delivery/collections -> 404. Thu COD chua co endpoint (trung DEF-L3-004).
A15: L4-UJ-07 | B15: User Journey | C15: FT-08 AC-01; AC-02; AC-03; BR-017; SC-03 | D15: FT-08 | E15: P1 | F15: Customer + Sales Manager | G15: /profile/orders/:orderId → luồng huỷ đơn đã thanh toán | H15: Đơn đã PAID qua SePay | I15: 1. Khách gửi yêu cầu huỷ đơn đã thanh toán 2. Sales Manager duyệt 3. Sales tạo đơn thay thế 4. Xem số dư credit của khách | J15: KHÔNG có tuỳ chọn hoàn tiền ở bất kỳ màn hình nào Giá trị đã trả được chuyển sang đơn thay thế Phần dư hiện thành credit của đúng khách đó | K15: No | L15: Pass
A16: L4-UJ-08 | B16: User Journey | C16: FT-08 AC-05; BR-019; SC-03 | D16: FT-08 | E16: P2 | F16: Warehouse Staff | G16: /warehouse/inv-management/quarantine · /warehouse/purchase/quality-inspection | H16: Có hàng trả về do lỗi chất lượng | I16: 1. Ghi nhận hàng trả về 2. Mở khu cách ly, kiểm tra hàng 3. Nhập kết quả kiểm định: đạt / hỏng 4. Thử đưa hàng chưa kiểm định vào tồn bán được | J16: Hàng trả về vào khu cách ly, KHÔNG cộng vào tồn khả dụng Chỉ sau kiểm định + phê duyệt mới được nhập lại Thao tác bỏ qua kiểm định bị chặn | K16: No | L16: Pass
A17: ▶ SC-06 — Mua hàng, chuyển kho và kiểm soát tồn kho
A18: L4-UJ-09 | B18: User Journey | C18: FT-06 AC-01; AC-03; AC-05; BR-014; SC-06 | D18: FT-06 | E18: P1 | F18: CEO + Warehouse Staff | G18: CEOPortal tab "purchase-orders" → /warehouse/purchase/goods-receipt | H18: Nhà cung cấp SUP-01 đã tạo SKU-001 tồn = 10 | I18: 1. CEO tạo PO, phát hành, gửi kho 2. Kho tạo phiếu nhập từ PO 3. Nhập số lượng nhận + hàng hỏng/thiếu 4. Post phiếu nhập 5. Xem lại tồn kho | J18: Tồn kho KHÔNG đổi ở bước 1-3 Sau khi post: tồn tăng đúng phần đạt chất lượng Hàng hỏng ghi riêng, không vào tồn bán được Phiếu đã post không sửa được | K18: No | L18: Pass
A19: L4-UJ-10 | B19: User Journey | C19: FT-11 AC-01; AC-02; AC-03; BR-035; SC-06 | D19: FT-11 | E19: P1 | F19: Warehouse Staff | G19: /warehouse/transfer/stock-transfer → /warehouse/purchase/receiving-comparison | H19: WH-TRADE có SKU-001 tồn 20; WH-PROD tồn 5 | I19: 1. Tạo phiếu chuyển 10 từ WH-TRADE sang WH-PROD 2. Post phiếu xuất 3. Kho nhận ghi nhận thực nhận 9 (thiếu 1) 4. Xem chênh lệch | J19: Sau bước 2: WH-TRADE giảm 10, hiện 10 đang chuyển Sau bước 3: WH-PROD tăng 9, tạo bản ghi chênh lệch 1 Số chênh lệch KHÔNG tự cân bằng | K19: No | L19: Pass
A20: L4-UJ-11 | B20: User Journey | C20: FT-12 AC-01; AC-02; AC-03; BR-044; SC-06 | D20: FT-12 | E20: P1 | F20: Warehouse Staff + CEO | G20: /warehouse/inv-management/inventory-count · /warehouse/inv-management/stock-adjustment | H20: Ngưỡng duyệt điều chỉnh đã cấu hình | I20: 1. Kho mở phiên kiểm kê, hệ thống chốt số lý thuyết 2. Nhập số đếm thực tế lệch 3. Gửi đề nghị điều chỉnh vượt ngưỡng 4. CEO duyệt và post | J20: Số lý thuyết bị khoá, không sửa được Tồn kho KHÔNG đổi cho tới khi post Vượt ngưỡng bắt buộc CEO duyệt Sau post: tồn đổi đúng phần chênh lệch | K20: No | L20: Blocked | M20: DEF-L4-003 | N20: GET /api/inventory/count-sessions -> 404. Phien kiem ke chua trien khai (trung DEF-L3-005).
A21: L4-UJ-12 | B21: User Journey | C21: FT-12 AC-05; BR-045; SC-06 | D21: FT-12 | E21: P2 | F21: Warehouse Staff | G21: /warehouse/production/issue | H21: Có vật tư trong kho | I21: 1. Tạo phiếu xuất vật tư cho sản xuất ngoài 2. Bỏ trống người nhận / số phiếu / ảnh ký, bấm lưu 3. Nhập đủ và lưu lại | J21: Bước 2 bị chặn, chỉ rõ trường còn thiếu Bước 3 thành công, tồn giảm đúng 1 lần, ảnh ký lưu kèm | K21: No | L21: Pass
A22: L4-UJ-13 | B22: User Journey | C22: FT-12 AC-04; BV-03; BR-049; SC-06 | D22: FT-12 | E22: P2 | F22: Warehouse Staff | G22: /warehouse/inv-management · thông báo hệ thống | H22: SKU-002 có ngưỡng tồn thấp đã cấu hình; tồn hiện tại = ngưỡng + 1 | I22: 1. Xuất 1 đơn vị để tồn bằng đúng ngưỡng 2. Mở danh sách cảnh báo tồn thấp 3. Xuất thêm 1 đơn vị nữa rồi xem lại danh sách | J22: Trước ngưỡng: không có cảnh báo Từ ngưỡng trở xuống: hiện ĐÚNG 1 cảnh báo kèm số lượng hiện tại, ngưỡng, kho và hành động tiếp theo Xuống thêm không sinh cảnh báo thứ hai mà cập nhật cảnh báo đang có | K22: No | L22: Blocked | M22: DEF-L4-003 | N22: GET /api/inventory/low-stock-alerts -> 404. Canh bao ton thap chua co endpoint (trung DEF-L3-005).
A23: ▶ Template Row — copy khi thêm case mới
A24: L4-XX-[NN] | B24: [Critical Path | User Journey | Permission | Session | Responsive] | C24: [FT-xx AC/NAC/BV-xx; BR-xxx; SC-xx] | D24: [FT-xx] | E24: P2 | F24: [Vai trò] | G24: [/route hoặc tên màn hình] | H24: [TK test + trạng thái DB + sandbox] | I24: 1. ... 2. ... 3. ... | J24: [Người dùng THẤY gì trên màn hình] | K24: No | L24: Not Run

Sheet L4-Permissions
A1: L4-Permissions | Ma trận uỷ quyền trên giao diện — 7 vai trò của SRS v2 | NFR-SEC03; FT-09 NAC-01/NAC-02
A2: HOW TO USE: (1) Đọc Introduction (2) Đối chiếu route + data-testid với FE trước khi viết script (3) Chạy npx playwright test trên staging (4) Cập nhật Status (5) Ghi Defect ID khi Fail
A4: Test ID | B4: Coverage Technique | C4: SRS Reference | D4: Feature | E4: Priority | F4: Actor (Role) | G4: Entry Point (URL / Page) | H4: Precondition (DB + Auth + Sandbox) | I4: Test Steps (Browser Actions) | J4: Expected UI Result | K4: Negative? | L4: Status | M4: Defect ID | N4: Notes
A5: ▶ Chặn truy cập theo vai trò (kiểm tra ở UI, không chỉ ẩn nút)
A6: L4-PM-01 | B6: Permission | C6: NFR-SEC03; FT-01 NAC-05 | D6: FT-01 | E6: P1 | F6: Guest | G6: /checkout (gõ thẳng URL) | H6: Chưa đăng nhập | I6: 1. Gõ trực tiếp /checkout vào thanh địa chỉ 2. Quan sát | J6: Bị chuyển về /login Nội dung checkout KHÔNG render | K6: Yes | L6: Pass
A7: L4-PM-02 | B7: Permission | C7: NFR-SEC03 | D7: FT-09 | E7: P1 | F7: Customer | G7: /warehouse/dashboard (gõ thẳng URL) | H7: Đăng nhập vai trò Customer | I7: 1. Gõ URL portal kho 2. Quan sát | J7: Từ chối truy cập / chuyển hướng Không hiển thị dữ liệu kho | K7: Yes | L7: Pass
A8: L4-PM-03 | B8: Permission | C8: NFR-SEC03; BR-027 | D8: FT-02 | E8: P1 | F8: Sales Staff | G8: CEOPortal tab "price-negotiation" | H8: Đăng nhập vai trò Sales Staff | I8: 1. Mở màn hình duyệt báo giá cấp CEO 2. Thử bấm nút duyệt (nếu render) | J8: Không vào được màn hình; nếu gọi API trực tiếp -> 403 Trạng thái báo giá không đổi | K8: Yes | L8: Pass
A9: L4-PM-04 | B9: Permission | C9: NFR-SEC03; FT-09 NAC-02 | D9: FT-09 | E9: P1 | F9: Admin | G9: CEOPortal tab "price-negotiation" · /warehouse/inv-management/stock-adjustment | H9: Đăng nhập vai trò Admin | I9: 1. Thử duyệt báo giá 2. Thử duyệt điều chỉnh tồn kho | J9: Admin KHÔNG thực hiện được phê duyệt nghiệp vụ (SRS v2 tách vai trò) Các thao tác quản trị kỹ thuật vẫn dùng bình thường | K9: Yes | L9: Fail | M9: DEF-L4-005 | N9: API chan Admin dung (ceo-decision 403, inventory adjust 403) NHUNG UI van cho Admin mo /warehouse/inv-management/stock-adjustment va /ceo/* (App.tsx:76,79).
A10: L4-PM-05 | B10: Permission | C10: NFR-SEC03; FT-04 NAC-04 | D10: FT-04 | E10: P1 | F10: Sales Staff | G10: /sales-manager/change-requests | H10: Có yêu cầu đổi Sales đang mở | I10: 1. Mở chi tiết yêu cầu đổi Sales của chính mình 2. Tìm nút Duyệt / Từ chối | J10: Sales Staff chỉ giải trình được, KHÔNG có quyền duyệt/từ chối/xoá | K10: Yes | L10: Pass
A11: L4-PM-06 | B11: Permission | C11: NFR-SEC03; FT-05 NAC-05 | D11: FT-05 | E11: P1 | F11: Warehouse Staff | G11: /warehouse/fulfillment/orders (kho khác) | H11: Nhân viên thuộc WH-TRADE | I11: 1. Thử mở/thao tác phiếu của WH-PROD | J11: Bị chặn theo phạm vi kho được gán | K11: Yes | L11: Pass
A12: L4-PM-07 | B12: Permission | C12: NFR-SEC03; FT-01 NAC-05 | D12: FT-01 | E12: P1 | F12: Customer | G12: /profile/orders/:orderId của khách khác | H12: Đơn thuộc khách khác | I12: 1. Đổi id trên URL sang đơn của khách khác | J12: Không hiển thị dữ liệu; báo không tìm thấy hoặc từ chối truy cập | K12: Yes | L12: Pass
A13: ▶ Template Row — copy khi thêm case mới
A14: L4-XX-[NN] | B14: [Critical Path | User Journey | Permission | Session | Responsive] | C14: [FT-xx AC/NAC/BV-xx; BR-xxx; SC-xx] | D14: [FT-xx] | E14: P2 | F14: [Vai trò] | G14: [/route hoặc tên màn hình] | H14: [TK test + trạng thái DB + sandbox] | I14: 1. ... 2. ... 3. ... | J14: [Người dùng THẤY gì trên màn hình] | K14: No | L14: Not Run

Sheet L4-SessionManagement
A1: L4-SessionManagement | Phiên đăng nhập, refresh token, đa tab | NFR-SEC02
A2: HOW TO USE: (1) Đọc Introduction (2) Đối chiếu route + data-testid với FE trước khi viết script (3) Chạy npx playwright test trên staging (4) Cập nhật Status (5) Ghi Defect ID khi Fail
A4: Test ID | B4: Coverage Technique | C4: SRS Reference | D4: Feature | E4: Priority | F4: Actor (Role) | G4: Entry Point (URL / Page) | H4: Precondition (DB + Auth + Sandbox) | I4: Test Steps (Browser Actions) | J4: Expected UI Result | K4: Negative? | L4: Status | M4: Defect ID | N4: Notes
A5: ▶ Vòng đời phiên
A6: L4-SM-01 | B6: Session | C6: NFR-SEC02 | D6: FT-01 | E6: P1 | F6: Customer | G6: /products | H6: Đăng nhập thành công, access token sắp hết hạn | I6: 1. Ở yên trên trang cho tới khi access token hết hạn 2. Thực hiện một thao tác cần xác thực (thêm giỏ hàng) | J6: Hệ thống tự refresh ngầm, thao tác thành công Người dùng KHÔNG bị đá ra trang đăng nhập | K6: No | L6: Pass
A7: L4-SM-02 | B7: Session | C7: NFR-SEC02 | D7: FT-01 | E7: P1 | F7: Customer | G7: /products | H7: Refresh token bị thu hồi (đăng xuất ở nơi khác) | I7: 1. Thu hồi refresh token phía server 2. Thực hiện thao tác cần xác thực | J7: Bị chuyển về /login Dữ liệu phiên bị xoá khỏi trình duyệt | K7: Yes | L7: Pass
A8: L4-SM-03 | B8: Session | C8: NFR-SEC02 | D8: FT-01 | E8: P2 | F8: Customer | G8: 2 tab cùng lúc | H8: Đăng nhập ở tab A và tab B | I8: 1. Đăng xuất ở tab A 2. Chuyển sang tab B, thao tác | J8: Tab B cũng mất phiên, chuyển về đăng nhập (không dùng token đã thu hồi) | K8: Yes | L8: Pass
A9: L4-SM-04 | B9: Session | C9: FT-01 AC-05; BR-025 | D9: FT-01 | E9: P1 | F9: Customer | G9: /cart | H9: Giỏ hàng có 2 dòng, snapshot còn hạn | I9: 1. Đăng xuất 2. Đăng nhập lại 3. Mở giỏ hàng | J9: Giỏ hàng được khôi phục đúng dòng + số lượng (giỏ gắn tài khoản) | K9: No | L9: Pass
A10: L4-SM-05 | B10: Session | C10: FT-01 NAC-03; BV-01; BR-025 | D10: FT-01 | E10: P1 | F10: Customer | G10: /cart | H10: Snapshot giỏ tạo cách đây 24:00:01 | I10: 1. Mở lại giỏ hàng 2. Thử bấm thanh toán | J10: Hiện cảnh báo giá đã hết hạn bằng tiếng Việt Bị chặn cho tới khi bấm làm mới và xác nhận lại giá | K10: Yes | L10: Fail | M10: DEF-L4-007 | N10: Sau khi day Carts.UpdatedAt lui 24:00:01, gio van cho thanh toan; khong co canh bao gia het han va khong bat lam moi gia. Khong tim thay logic 24h o CartService lan Cart.jsx.
A11: ▶ Template Row — copy khi thêm case mới
A12: L4-XX-[NN] | B12: [Critical Path | User Journey | Permission | Session | Responsive] | C12: [FT-xx AC/NAC/BV-xx; BR-xxx; SC-xx] | D12: [FT-xx] | E12: P2 | F12: [Vai trò] | G12: [/route hoặc tên màn hình] | H12: [TK test + trạng thái DB + sandbox] | I12: 1. ... 2. ... 3. ... | J12: [Người dùng THẤY gì trên màn hình] | K12: No | L12: Not Run

Sheet L4-Responsive (Optional)
A1: L4-Responsive | NFR-U01 (>= 375px) · NFR-U02 (tiếng Việt) · NFR-U03 (checkout <= 4 bước)
A2: HOW TO USE: (1) Đọc Introduction (2) Đối chiếu route + data-testid với FE trước khi viết script (3) Chạy npx playwright test trên staging (4) Cập nhật Status (5) Ghi Defect ID khi Fail
A4: Test ID | B4: Coverage Technique | C4: SRS Reference | D4: Feature | E4: Priority | F4: Actor (Role) | G4: Entry Point (URL / Page) | H4: Precondition (DB + Auth + Sandbox) | I4: Test Steps (Browser Actions) | J4: Expected UI Result | K4: Negative? | L4: Status | M4: Defect ID | N4: Notes
A5: ▶ Giao diện đáp ứng và ngôn ngữ
A6: L4-RS-01 | B6: Responsive | C6: NFR-U01 | D6: FT-01 | E6: P2 | F6: Customer | G6: /products, /cart, /checkout @ 375px | H6: Viewport 375x812 (iPhone SE/mini) | I6: 1. Duyệt sản phẩm, thêm giỏ, mở checkout ở 375px 2. Kiểm tra cuộn ngang | J6: Không có cuộn ngang Các nút thao tác chính bấm được | K6: No | L6: Pass
A7: L4-RS-02 | B7: Responsive | C7: NFR-U01 | D7: FT-07 | E7: P2 | F7: Sales Staff | G7: /sales/delivery/collection @ 375px | H7: Viewport 375px | I7: 1. Mở màn hình ghi nhận giao hàng và thu tiền trên mobile | J7: Nhập liệu và tải ảnh dùng được trên điện thoại (Sales dùng ngoài đường) | K7: No | L7: Pass
A8: L4-RS-03 | B8: Localization | C8: NFR-U02 | D8: FT-01 | E8: P2 | F8: Customer | G8: Toàn bộ luồng đặt hàng | H8: Ngôn ngữ hệ thống mặc định | I8: 1. Đi hết luồng đặt hàng, chụp lại mọi thông báo lỗi/xác nhận | J8: 100% văn bản người dùng thấy là tiếng Việt Định dạng tiền tệ và ngày theo chuẩn VN | K8: No | L8: Pass
A9: L4-RS-04 | B9: Usability | C9: NFR-U03 | D9: FT-01 | E9: P2 | F9: Customer | G9: /cart → hoàn tất đặt hàng | H9: Giỏ đã có hàng, địa chỉ mặc định đã lưu | I9: 1. Đếm số lần click/số trang từ giỏ tới khi chọn xong phương thức thanh toán | J9: Tối đa 4 click/trang | K9: No | L9: Pass
A10: ▶ Template Row — copy khi thêm case mới
A11: L4-XX-[NN] | B11: [Critical Path | User Journey | Permission | Session | Responsive] | C11: [FT-xx AC/NAC/BV-xx; BR-xxx; SC-xx] | D11: [FT-xx] | E11: P2 | F11: [Vai trò] | G11: [/route hoặc tên màn hình] | H11: [TK test + trạng thái DB + sandbox] | I11: 1. ... 2. ... 3. ... | J11: [Người dùng THẤY gì trên màn hình] | K11: No | L11: Not Run

Sheet L4-AdminMarketing
A1: L4-AdminMarketing | MỚI v2.1 | Quản trị người dùng, cấu hình, marketing, đổi/trả trên giao diện | FT-09; FT-10; FT-08
A2: HOW TO USE: (1) Đối chiếu route + data-testid với FE (2) Chạy npx playwright test trên staging (3) Cập nhật Status (4) Ghi Defect ID khi Fail
A4: Test ID | B4: Coverage Technique | C4: SRS Reference | D4: Feature | E4: Priority | F4: Actor (Role) | G4: Entry Point (URL / Page) | H4: Precondition (DB + Auth + Sandbox) | I4: Test Steps (Browser Actions) | J4: Expected UI Result | K4: Negative? | L4: Status | M4: Defect ID | N4: Notes
A5: ▶ Block: SC-04 — Quản trị, bảng điều khiển, cảnh báo và nhật ký | FT-09
A6: L4-AM-01 | B6: User Journey | C6: FT-09 AC-04; BR-022; NFR-SEC02; SC-04 | D6: FT-09 | E6: P1 | F6: Admin | G6: /admin/users (AdminPortal) | H6: TK Admin Email nhân viên mới chưa tồn tại | I6: 1. Đăng nhập Admin, mở quản lý người dùng 2. Tạo tài khoản nhân viên mới, chọn vai trò 3. Đổi vai trò của tài khoản vừa tạo 4. Vô hiệu hoá tài khoản 5. Đăng nhập bằng tài khoản đó | J6: Tạo/đổi vai trò thành công, hiện trong danh sách Sau khi vô hiệu hoá: KHÔNG đăng nhập được Mọi thay đổi đều xuất hiện trong nhật ký kiểm toán | K6: No | L6: Pass
A7: L4-AM-02 | B7: User Journey | C7: FT-09 AC-03; NAC-04; BV-02; BR-050; SC-04 | D7: FT-09 | E7: P1 | F7: Admin + Customer | G7: /admin/settings → /cart | H7: Có giỏ hàng đang giữ giá và đơn đã hoàn tất | I7: 1. Admin đổi bảng chiết khấu, đặt hiệu lực từ ngày mai 2. Khách mở lại giỏ đang giữ giá 3. Khách mở lại đơn đã hoàn tất | J7: Giỏ giữ NGUYÊN giá cũ Đơn cũ không bị tính lại Cấu hình mới chỉ áp dụng từ thời điểm hiệu lực | K7: No | L7: Pass
A8: L4-AM-03 | B8: Permission | C8: FT-09 NAC-03; BR-048; NFR-SEC08; SC-04 | D8: FT-09 | E8: P1 | F8: Admin | G8: /admin/audit-log | H8: Có bản ghi nhật ký | I8: 1. Mở nhật ký kiểm toán 2. Tìm nút sửa/xoá bản ghi 3. Thử xuất CSV | J8: KHÔNG có chức năng sửa/xoá Xuất CSV hoạt động, PII đã được che | K8: Yes | L8: Pass
A9: L4-AM-04 | B9: User Journey | C9: FT-09 AC-05; BV-03; BR-049; NFR-A04; SC-04 | D9: FT-09 | E9: P2 | F9: Admin | G9: /admin/settings (system health) | H9: Có job đã chạy thành công, job thất bại và job chưa chạy | I9: 1. Mở màn hình theo dõi job 2. Đối chiếu trạng thái từng job | J9: Job lỗi hiển thị rõ số lần thử lại và lỗi Job chưa chạy KHÔNG bị hiển thị là khoẻ mạnh | K9: No | L9: Pass
A10: ▶ Block: SC-05 — Marketing hỗ trợ AI và đăng Facebook · Đổi trả (SC-03) | FT-10; FT-08
A11: L4-AM-05 | B11: User Journey | C11: FT-10 AC-01; AC-02; AC-03; BR-046; NFR-P07; SC-05 | D11: FT-10 | E11: P1 | F11: Sales Staff + Sales Manager | G11: /admin/ai-marketing · /admin/marketing-history | H11: TK Sales Staff và Sales Manager Dịch vụ AI/Make sandbox bật | I11: 1. Sales tạo bài, yêu cầu sinh nội dung + ảnh 2. Gửi duyệt 3. Sales Manager xem, duyệt và hẹn giờ 4. Chờ tới giờ, kiểm tra kết quả | J11: Khi AI đang xử lý: màn hình báo đang xử lý, không treo Sales KHÔNG tự đăng được bài chưa duyệt Sau khi đăng: lưu link bài, hiện trong lịch sử | K11: No | L11: Blocked | M11: DEF-L4-004 | N11: Workbook ghi /admin/ai-marketing nhung route do la stub ComingSoon (AdminPortal.tsx:205-207). Chuc nang that o /sales/ai-content-studio.
A12: L4-AM-06 | B12: Permission | C12: FT-10 NAC-01; NAC-02; BR-046; NFR-SEC03; SC-05 | D12: FT-10 | E12: P1 | F12: Sales Staff | G12: /admin/ai-marketing · /admin/marketing-history | H12: Bài M1 do chính Sales này tạo, đang chờ duyệt | I12: 1. Mở bài của mình 2. Tìm nút Duyệt | J12: Không có/không dùng được nút Duyệt Gọi API trực tiếp cũng bị từ chối | K12: Yes | L12: Pass
A13: L4-AM-09 | B13: User Journey | C13: FT-10 NAC-03; BV-01; BV-02; SC-05 | D13: FT-10 | E13: P1 | F13: Sales Manager | G13: /admin/ai-marketing | H13: Có bài đang chờ duyệt Hàng đợi đã có 30 bài được hẹn giờ | I13: 1. Duyệt bài và chọn thời điểm đăng ĐÃ QUA 2. Chọn lại thời điểm trong tương lai 3. Với hàng đợi đã đủ 30 bài, thử hẹn thêm bài thứ 31 | J13: Bước 1 bị chặn, báo lỗi tiếng Việt rõ ràng Bước 2 thành công, bài chuyển sang đã hẹn giờ Bước 3 bị chặn và hiển thị giới hạn hàng đợi; lịch cũ không đổi | K13: Yes | L13: Pass
A14: L4-AM-10 | B14: User Journey | C14: FT-10 NAC-04; BV-03; NFR-SEC07; SC-05 | D14: FT-10 | E14: P2 | F14: Sales Staff | G14: /admin/ai-marketing | H14: Có bài nháp File thử: .exe đổi đuôi .png và ảnh vượt giới hạn dung lượng | I14: 1. Tải lên file sai định dạng 2. Tải lên ảnh vượt dung lượng cho phép 3. Thử gửi duyệt bài | J14: Cả hai file đều bị từ chối kèm thông báo rõ lý do File không được gắn vào bài Bài không gửi duyệt được khi đính kèm không hợp lệ | K14: Yes | L14: Blocked | M14: DEF-L4-003 | N14: POST /api/marketing-posts/{id}/media -> 404. Upload media chua trien khai; khong kiem duoc NFR-SEC07.
A15: L4-AM-11 | B15: User Journey | C15: FT-10 AC-04; AC-05; BR-003; BR-049; SC-05 | D15: FT-10 | E15: P2 | F15: Admin + Sales Manager | G15: /admin/marketing-history | H15: Một bài đăng thành công, một bài bị Facebook trả lỗi Khách A đang thuộc Sales S1 | I15: 1. Mở lịch sử đăng bài, xem số liệu tương tác của bài thành công 2. Xem bài lỗi, bấm thử lại 3. Kiểm tra người phụ trách của khách A sau khi khách vào từ bài viết | J15: Số liệu tương tác gắn đúng bài đã đăng Bài lỗi giữ nguyên nội dung đã duyệt, thử lại KHÔNG tạo bài trùng trên Facebook Khách A VẪN thuộc Sales S1 | K15: No | L15: Blocked | M15: DEF-L4-003 | N15: GET /api/marketing-posts/{id}/metrics -> 404. Chi so tuong tac chua trien khai.
A16: L4-AM-07 | B16: User Journey | C16: FT-08 AC-05; BR-019; SC-03 | D16: FT-08 | E16: P1 | F16: Customer + Sales Manager + Sales Staff | G16: /profile/orders/:orderId → /sales/pickup-arrangement | H16: Đơn đã giao, khách báo lỗi 2 sản phẩm | I16: 1. Khách tạo yêu cầu đổi/trả kèm ảnh 2. Sales Manager duyệt 3. Sales lên lịch thu hồi 4. Sales xác nhận đã thu hồi hàng | J16: Khách theo dõi được tiến độ Sau khi thu hồi: hàng KHÔNG cộng vào tồn bán được Sales Staff không tự duyệt được yêu cầu | K16: No | L16: Blocked | M16: DEF-L4-004 | N16: Workbook ghi /sales/pickup-arrangement nhung route khong ton tai trong SalesPortal.tsx (roi vao catch-all ve Dashboard).
A17: L4-AM-08 | B17: User Journey | C17: FT-08 AC-03; BV-02; BR-042; BR-043; SC-03 | D17: FT-08 | E17: P1 | F17: Sales Staff | G17: /sales/orders (tạo đơn thay thế) | H17: Yêu cầu đổi đã duyệt; P1 giá gốc 50.000; P2 giá hiện hành 70.000 | I17: 1. Tạo đơn thay thế CÙNG mã P1 2. Tạo đơn thay thế đổi sang mã P2 3. Đối chiếu số tiền hiển thị | J17: Cùng mã: giữ giá gốc 50.000, không phát sinh phải thu Khác mã: dùng giá 70.000, chênh lệch hiển thị rõ cho khách | K17: No | L17: Pass
